[2022-08-17 20:31:46,846] {taskinstance.py:1179} INFO - Dependencies all met for <TaskInstance: unitronics_ETL_v01.extract manual__2022-08-17T20:06:39.649803+00:00 [queued]>
[2022-08-17 20:31:46,856] {taskinstance.py:1179} INFO - Dependencies all met for <TaskInstance: unitronics_ETL_v01.extract manual__2022-08-17T20:06:39.649803+00:00 [queued]>
[2022-08-17 20:31:46,856] {taskinstance.py:1376} INFO - 
--------------------------------------------------------------------------------
[2022-08-17 20:31:46,857] {taskinstance.py:1377} INFO - Starting attempt 6 of 6
[2022-08-17 20:31:46,857] {taskinstance.py:1378} INFO - 
--------------------------------------------------------------------------------
[2022-08-17 20:31:46,872] {taskinstance.py:1397} INFO - Executing <Task(PythonOperator): extract> on 2022-08-17 20:06:39.649803+00:00
[2022-08-17 20:31:46,875] {standard_task_runner.py:52} INFO - Started process 3635 to run task
[2022-08-17 20:31:46,879] {standard_task_runner.py:79} INFO - Running: ['***', 'tasks', 'run', 'unitronics_ETL_v01', 'extract', 'manual__2022-08-17T20:06:39.649803+00:00', '--job-id', '104', '--raw', '--subdir', 'DAGS_FOLDER/unitronics_ETL.py', '--cfg-path', '/tmp/tmpb55ynxuj', '--error-file', '/tmp/tmp2ruombul']
[2022-08-17 20:31:46,880] {standard_task_runner.py:80} INFO - Job 104: Subtask extract
[2022-08-17 20:31:46,947] {task_command.py:371} INFO - Running <TaskInstance: unitronics_ETL_v01.extract manual__2022-08-17T20:06:39.649803+00:00 [running]> on host 8c93e37464e5
[2022-08-17 20:31:47,026] {taskinstance.py:1591} INFO - Exporting the following env vars:
AIRFLOW_CTX_DAG_OWNER=Cavefish
AIRFLOW_CTX_DAG_ID=unitronics_ETL_v01
AIRFLOW_CTX_TASK_ID=extract
AIRFLOW_CTX_EXECUTION_DATE=2022-08-17T20:06:39.649803+00:00
AIRFLOW_CTX_TRY_NUMBER=6
AIRFLOW_CTX_DAG_RUN_ID=manual__2022-08-17T20:06:39.649803+00:00
[2022-08-17 20:31:47,033] {taskinstance.py:1909} ERROR - Task failed with exception
Traceback (most recent call last):
  File "/home/airflow/.local/lib/python3.7/site-packages/airflow/operators/python.py", line 171, in execute
    return_value = self.execute_callable()
  File "/home/airflow/.local/lib/python3.7/site-packages/airflow/operators/python.py", line 189, in execute_callable
    return self.python_callable(*self.op_args, **self.op_kwargs)
  File "/opt/airflow/dags/unitronics_ETL.py", line 76, in extractData
    files = os.listdir(dir_name)
FileNotFoundError: [Errno 2] No such file or directory: '/Unitronics Data Logs/'
[2022-08-17 20:31:47,046] {taskinstance.py:1420} INFO - Marking task as FAILED. dag_id=unitronics_ETL_v01, task_id=extract, execution_date=20220817T200639, start_date=20220817T203146, end_date=20220817T203147
[2022-08-17 20:31:47,058] {standard_task_runner.py:97} ERROR - Failed to execute job 104 for task extract ([Errno 2] No such file or directory: '/Unitronics Data Logs/'; 3635)
[2022-08-17 20:31:47,091] {local_task_job.py:156} INFO - Task exited with return code 1
[2022-08-17 20:31:47,137] {local_task_job.py:273} INFO - 0 downstream tasks scheduled from follow-on schedule check
