[2022-08-17 19:07:13,710] {taskinstance.py:1179} INFO - Dependencies all met for <TaskInstance: unitronics_ETL_v01.extract scheduled__2022-08-16T00:00:00+00:00 [queued]>
[2022-08-17 19:07:13,720] {taskinstance.py:1179} INFO - Dependencies all met for <TaskInstance: unitronics_ETL_v01.extract scheduled__2022-08-16T00:00:00+00:00 [queued]>
[2022-08-17 19:07:13,721] {taskinstance.py:1376} INFO - 
--------------------------------------------------------------------------------
[2022-08-17 19:07:13,721] {taskinstance.py:1377} INFO - Starting attempt 2 of 6
[2022-08-17 19:07:13,721] {taskinstance.py:1378} INFO - 
--------------------------------------------------------------------------------
[2022-08-17 19:07:13,736] {taskinstance.py:1397} INFO - Executing <Task(PythonOperator): extract> on 2022-08-16 00:00:00+00:00
[2022-08-17 19:07:13,740] {standard_task_runner.py:52} INFO - Started process 552 to run task
[2022-08-17 19:07:13,746] {standard_task_runner.py:79} INFO - Running: ['***', 'tasks', 'run', 'unitronics_ETL_v01', 'extract', 'scheduled__2022-08-16T00:00:00+00:00', '--job-id', '11', '--raw', '--subdir', 'DAGS_FOLDER/unitronics_ETL.py', '--cfg-path', '/tmp/tmp0p3kbf9p', '--error-file', '/tmp/tmp9g6751hj']
[2022-08-17 19:07:13,747] {standard_task_runner.py:80} INFO - Job 11: Subtask extract
[2022-08-17 19:07:13,814] {task_command.py:371} INFO - Running <TaskInstance: unitronics_ETL_v01.extract scheduled__2022-08-16T00:00:00+00:00 [running]> on host ea4c9b9e2e97
[2022-08-17 19:07:13,888] {taskinstance.py:1591} INFO - Exporting the following env vars:
AIRFLOW_CTX_DAG_OWNER=Cavefish
AIRFLOW_CTX_DAG_ID=unitronics_ETL_v01
AIRFLOW_CTX_TASK_ID=extract
AIRFLOW_CTX_EXECUTION_DATE=2022-08-16T00:00:00+00:00
AIRFLOW_CTX_TRY_NUMBER=2
AIRFLOW_CTX_DAG_RUN_ID=scheduled__2022-08-16T00:00:00+00:00
[2022-08-17 19:07:13,896] {taskinstance.py:1909} ERROR - Task failed with exception
Traceback (most recent call last):
  File "/home/airflow/.local/lib/python3.7/site-packages/airflow/operators/python.py", line 171, in execute
    return_value = self.execute_callable()
  File "/home/airflow/.local/lib/python3.7/site-packages/airflow/operators/python.py", line 189, in execute_callable
    return self.python_callable(*self.op_args, **self.op_kwargs)
  File "/opt/airflow/dags/unitronics_ETL.py", line 95, in extractData
    device_df = concatDataFrame(super_df_device)
  File "/opt/airflow/dags/unitronics_ETL.py", line 54, in concatDataFrame
    df = pd.concat(df, axis=0)
  File "/home/airflow/.local/lib/python3.7/site-packages/pandas/util/_decorators.py", line 311, in wrapper
    return func(*args, **kwargs)
  File "/home/airflow/.local/lib/python3.7/site-packages/pandas/core/reshape/concat.py", line 304, in concat
    sort=sort,
  File "/home/airflow/.local/lib/python3.7/site-packages/pandas/core/reshape/concat.py", line 351, in __init__
    raise ValueError("No objects to concatenate")
ValueError: No objects to concatenate
[2022-08-17 19:07:13,910] {taskinstance.py:1420} INFO - Marking task as UP_FOR_RETRY. dag_id=unitronics_ETL_v01, task_id=extract, execution_date=20220816T000000, start_date=20220817T190713, end_date=20220817T190713
[2022-08-17 19:07:13,921] {standard_task_runner.py:97} ERROR - Failed to execute job 11 for task extract (No objects to concatenate; 552)
[2022-08-17 19:07:13,956] {local_task_job.py:156} INFO - Task exited with return code 1
[2022-08-17 19:07:14,060] {local_task_job.py:273} INFO - 0 downstream tasks scheduled from follow-on schedule check
[2022-08-17 19:34:42,182] {taskinstance.py:1179} INFO - Dependencies all met for <TaskInstance: unitronics_ETL_v01.extract scheduled__2022-08-16T00:00:00+00:00 [queued]>
[2022-08-17 19:34:42,191] {taskinstance.py:1179} INFO - Dependencies all met for <TaskInstance: unitronics_ETL_v01.extract scheduled__2022-08-16T00:00:00+00:00 [queued]>
[2022-08-17 19:34:42,192] {taskinstance.py:1376} INFO - 
--------------------------------------------------------------------------------
[2022-08-17 19:34:42,192] {taskinstance.py:1377} INFO - Starting attempt 2 of 6
[2022-08-17 19:34:42,192] {taskinstance.py:1378} INFO - 
--------------------------------------------------------------------------------
[2022-08-17 19:34:42,207] {taskinstance.py:1397} INFO - Executing <Task(PythonOperator): extract> on 2022-08-16 00:00:00+00:00
[2022-08-17 19:34:42,211] {standard_task_runner.py:52} INFO - Started process 539 to run task
[2022-08-17 19:34:42,217] {standard_task_runner.py:79} INFO - Running: ['***', 'tasks', 'run', 'unitronics_ETL_v01', 'extract', 'scheduled__2022-08-16T00:00:00+00:00', '--job-id', '9', '--raw', '--subdir', 'DAGS_FOLDER/unitronics_ETL.py', '--cfg-path', '/tmp/tmpporeipy8', '--error-file', '/tmp/tmp2ng6vlri']
[2022-08-17 19:34:42,219] {standard_task_runner.py:80} INFO - Job 9: Subtask extract
[2022-08-17 19:34:42,290] {task_command.py:371} INFO - Running <TaskInstance: unitronics_ETL_v01.extract scheduled__2022-08-16T00:00:00+00:00 [running]> on host 2ea01d049be8
[2022-08-17 19:34:42,366] {taskinstance.py:1591} INFO - Exporting the following env vars:
AIRFLOW_CTX_DAG_OWNER=Cavefish
AIRFLOW_CTX_DAG_ID=unitronics_ETL_v01
AIRFLOW_CTX_TASK_ID=extract
AIRFLOW_CTX_EXECUTION_DATE=2022-08-16T00:00:00+00:00
AIRFLOW_CTX_TRY_NUMBER=2
AIRFLOW_CTX_DAG_RUN_ID=scheduled__2022-08-16T00:00:00+00:00
[2022-08-17 19:34:42,376] {taskinstance.py:1909} ERROR - Task failed with exception
Traceback (most recent call last):
  File "/home/airflow/.local/lib/python3.7/site-packages/airflow/operators/python.py", line 171, in execute
    return_value = self.execute_callable()
  File "/home/airflow/.local/lib/python3.7/site-packages/airflow/operators/python.py", line 189, in execute_callable
    return self.python_callable(*self.op_args, **self.op_kwargs)
  File "/opt/airflow/dags/unitronics_ETL.py", line 94, in extractData
    device_df = concatDataFrame(super_df_device)
  File "/opt/airflow/dags/unitronics_ETL.py", line 53, in concatDataFrame
    df = pd.concat(df, axis=0)
  File "/home/airflow/.local/lib/python3.7/site-packages/pandas/util/_decorators.py", line 311, in wrapper
    return func(*args, **kwargs)
  File "/home/airflow/.local/lib/python3.7/site-packages/pandas/core/reshape/concat.py", line 304, in concat
    sort=sort,
  File "/home/airflow/.local/lib/python3.7/site-packages/pandas/core/reshape/concat.py", line 351, in __init__
    raise ValueError("No objects to concatenate")
ValueError: No objects to concatenate
[2022-08-17 19:34:42,389] {taskinstance.py:1420} INFO - Marking task as UP_FOR_RETRY. dag_id=unitronics_ETL_v01, task_id=extract, execution_date=20220816T000000, start_date=20220817T193442, end_date=20220817T193442
[2022-08-17 19:34:42,403] {standard_task_runner.py:97} ERROR - Failed to execute job 9 for task extract (No objects to concatenate; 539)
[2022-08-17 19:34:42,427] {local_task_job.py:156} INFO - Task exited with return code 1
[2022-08-17 19:34:42,473] {local_task_job.py:273} INFO - 0 downstream tasks scheduled from follow-on schedule check
[2022-08-17 19:45:59,186] {taskinstance.py:1179} INFO - Dependencies all met for <TaskInstance: unitronics_ETL_v01.extract scheduled__2022-08-16T00:00:00+00:00 [queued]>
[2022-08-17 19:45:59,197] {taskinstance.py:1179} INFO - Dependencies all met for <TaskInstance: unitronics_ETL_v01.extract scheduled__2022-08-16T00:00:00+00:00 [queued]>
[2022-08-17 19:45:59,198] {taskinstance.py:1376} INFO - 
--------------------------------------------------------------------------------
[2022-08-17 19:45:59,198] {taskinstance.py:1377} INFO - Starting attempt 2 of 6
[2022-08-17 19:45:59,198] {taskinstance.py:1378} INFO - 
--------------------------------------------------------------------------------
[2022-08-17 19:45:59,213] {taskinstance.py:1397} INFO - Executing <Task(PythonOperator): extract> on 2022-08-16 00:00:00+00:00
[2022-08-17 19:45:59,257] {standard_task_runner.py:52} INFO - Started process 589 to run task
[2022-08-17 19:45:59,272] {standard_task_runner.py:79} INFO - Running: ['***', 'tasks', 'run', 'unitronics_ETL_v01', 'extract', 'scheduled__2022-08-16T00:00:00+00:00', '--job-id', '14', '--raw', '--subdir', 'DAGS_FOLDER/unitronics_ETL.py', '--cfg-path', '/tmp/tmpcm8ikw9p', '--error-file', '/tmp/tmp0fe35tiw']
[2022-08-17 19:45:59,277] {standard_task_runner.py:80} INFO - Job 14: Subtask extract
[2022-08-17 19:45:59,357] {task_command.py:371} INFO - Running <TaskInstance: unitronics_ETL_v01.extract scheduled__2022-08-16T00:00:00+00:00 [running]> on host 8c93e37464e5
[2022-08-17 19:45:59,429] {taskinstance.py:1591} INFO - Exporting the following env vars:
AIRFLOW_CTX_DAG_OWNER=Cavefish
AIRFLOW_CTX_DAG_ID=unitronics_ETL_v01
AIRFLOW_CTX_TASK_ID=extract
AIRFLOW_CTX_EXECUTION_DATE=2022-08-16T00:00:00+00:00
AIRFLOW_CTX_TRY_NUMBER=2
AIRFLOW_CTX_DAG_RUN_ID=scheduled__2022-08-16T00:00:00+00:00
[2022-08-17 19:45:59,436] {taskinstance.py:1909} ERROR - Task failed with exception
Traceback (most recent call last):
  File "/home/airflow/.local/lib/python3.7/site-packages/airflow/operators/python.py", line 171, in execute
    return_value = self.execute_callable()
  File "/home/airflow/.local/lib/python3.7/site-packages/airflow/operators/python.py", line 189, in execute_callable
    return self.python_callable(*self.op_args, **self.op_kwargs)
  File "/opt/airflow/dags/unitronics_ETL.py", line 112, in extractData
    return root
UnboundLocalError: local variable 'root' referenced before assignment
[2022-08-17 19:45:59,447] {taskinstance.py:1420} INFO - Marking task as UP_FOR_RETRY. dag_id=unitronics_ETL_v01, task_id=extract, execution_date=20220816T000000, start_date=20220817T194559, end_date=20220817T194559
[2022-08-17 19:45:59,458] {standard_task_runner.py:97} ERROR - Failed to execute job 14 for task extract (local variable 'root' referenced before assignment; 589)
[2022-08-17 19:45:59,486] {local_task_job.py:156} INFO - Task exited with return code 1
[2022-08-17 19:45:59,575] {local_task_job.py:273} INFO - 0 downstream tasks scheduled from follow-on schedule check
[2022-08-17 21:22:53,144] {taskinstance.py:1179} INFO - Dependencies all met for <TaskInstance: unitronics_ETL_v01.extract scheduled__2022-08-16T00:00:00+00:00 [queued]>
[2022-08-17 21:22:53,156] {taskinstance.py:1179} INFO - Dependencies all met for <TaskInstance: unitronics_ETL_v01.extract scheduled__2022-08-16T00:00:00+00:00 [queued]>
[2022-08-17 21:22:53,157] {taskinstance.py:1376} INFO - 
--------------------------------------------------------------------------------
[2022-08-17 21:22:53,157] {taskinstance.py:1377} INFO - Starting attempt 2 of 6
[2022-08-17 21:22:53,157] {taskinstance.py:1378} INFO - 
--------------------------------------------------------------------------------
[2022-08-17 21:22:53,176] {taskinstance.py:1397} INFO - Executing <Task(PythonOperator): extract> on 2022-08-16 00:00:00+00:00
[2022-08-17 21:22:53,181] {standard_task_runner.py:52} INFO - Started process 531 to run task
[2022-08-17 21:22:53,185] {standard_task_runner.py:79} INFO - Running: ['***', 'tasks', 'run', 'unitronics_ETL_v01', 'extract', 'scheduled__2022-08-16T00:00:00+00:00', '--job-id', '7', '--raw', '--subdir', 'DAGS_FOLDER/unitronics_ETL.py', '--cfg-path', '/tmp/tmpql19mq3k', '--error-file', '/tmp/tmpe213ji5q']
[2022-08-17 21:22:53,186] {standard_task_runner.py:80} INFO - Job 7: Subtask extract
[2022-08-17 21:22:53,276] {task_command.py:371} INFO - Running <TaskInstance: unitronics_ETL_v01.extract scheduled__2022-08-16T00:00:00+00:00 [running]> on host 1b0f89009e2c
[2022-08-17 21:22:53,362] {taskinstance.py:1591} INFO - Exporting the following env vars:
AIRFLOW_CTX_DAG_OWNER=Cavefish
AIRFLOW_CTX_DAG_ID=unitronics_ETL_v01
AIRFLOW_CTX_TASK_ID=extract
AIRFLOW_CTX_EXECUTION_DATE=2022-08-16T00:00:00+00:00
AIRFLOW_CTX_TRY_NUMBER=2
AIRFLOW_CTX_DAG_RUN_ID=scheduled__2022-08-16T00:00:00+00:00
[2022-08-17 21:22:53,372] {taskinstance.py:1909} ERROR - Task failed with exception
Traceback (most recent call last):
  File "/home/airflow/.local/lib/python3.7/site-packages/airflow/operators/python.py", line 171, in execute
    return_value = self.execute_callable()
  File "/home/airflow/.local/lib/python3.7/site-packages/airflow/operators/python.py", line 189, in execute_callable
    return self.python_callable(*self.op_args, **self.op_kwargs)
  File "/opt/airflow/dags/unitronics_ETL.py", line 76, in extractData
    files = os.listdir(dir_name)
FileNotFoundError: [Errno 2] No such file or directory: '/Unitronics Data Logs/'
[2022-08-17 21:22:53,383] {taskinstance.py:1420} INFO - Marking task as UP_FOR_RETRY. dag_id=unitronics_ETL_v01, task_id=extract, execution_date=20220816T000000, start_date=20220817T212253, end_date=20220817T212253
[2022-08-17 21:22:53,398] {standard_task_runner.py:97} ERROR - Failed to execute job 7 for task extract ([Errno 2] No such file or directory: '/Unitronics Data Logs/'; 531)
[2022-08-17 21:22:53,443] {local_task_job.py:156} INFO - Task exited with return code 1
[2022-08-17 21:22:53,487] {local_task_job.py:273} INFO - 0 downstream tasks scheduled from follow-on schedule check
