[2022-08-17 20:06:04,238] {taskinstance.py:1179} INFO - Dependencies all met for <TaskInstance: unitronics_ETL_v01.extract scheduled__2022-08-16T00:00:00+00:00 [queued]>
[2022-08-17 20:06:04,248] {taskinstance.py:1179} INFO - Dependencies all met for <TaskInstance: unitronics_ETL_v01.extract scheduled__2022-08-16T00:00:00+00:00 [queued]>
[2022-08-17 20:06:04,249] {taskinstance.py:1376} INFO - 
--------------------------------------------------------------------------------
[2022-08-17 20:06:04,249] {taskinstance.py:1377} INFO - Starting attempt 6 of 6
[2022-08-17 20:06:04,252] {taskinstance.py:1378} INFO - 
--------------------------------------------------------------------------------
[2022-08-17 20:06:04,270] {taskinstance.py:1397} INFO - Executing <Task(PythonOperator): extract> on 2022-08-16 00:00:00+00:00
[2022-08-17 20:06:04,275] {standard_task_runner.py:52} INFO - Started process 1935 to run task
[2022-08-17 20:06:04,279] {standard_task_runner.py:79} INFO - Running: ['***', 'tasks', 'run', 'unitronics_ETL_v01', 'extract', 'scheduled__2022-08-16T00:00:00+00:00', '--job-id', '57', '--raw', '--subdir', 'DAGS_FOLDER/unitronics_ETL.py', '--cfg-path', '/tmp/tmph3ol3xu4', '--error-file', '/tmp/tmpwa014mpz']
[2022-08-17 20:06:04,281] {standard_task_runner.py:80} INFO - Job 57: Subtask extract
[2022-08-17 20:06:04,359] {task_command.py:371} INFO - Running <TaskInstance: unitronics_ETL_v01.extract scheduled__2022-08-16T00:00:00+00:00 [running]> on host 8c93e37464e5
[2022-08-17 20:06:04,441] {taskinstance.py:1591} INFO - Exporting the following env vars:
AIRFLOW_CTX_DAG_OWNER=Cavefish
AIRFLOW_CTX_DAG_ID=unitronics_ETL_v01
AIRFLOW_CTX_TASK_ID=extract
AIRFLOW_CTX_EXECUTION_DATE=2022-08-16T00:00:00+00:00
AIRFLOW_CTX_TRY_NUMBER=6
AIRFLOW_CTX_DAG_RUN_ID=scheduled__2022-08-16T00:00:00+00:00
[2022-08-17 20:06:04,451] {taskinstance.py:1909} ERROR - Task failed with exception
Traceback (most recent call last):
  File "/home/airflow/.local/lib/python3.7/site-packages/airflow/operators/python.py", line 171, in execute
    return_value = self.execute_callable()
  File "/home/airflow/.local/lib/python3.7/site-packages/airflow/operators/python.py", line 189, in execute_callable
    return self.python_callable(*self.op_args, **self.op_kwargs)
  File "/opt/airflow/dags/unitronics_ETL.py", line 75, in extractData
    files = os.listdir(dir_name)
FileNotFoundError: [Errno 2] No such file or directory: 'C:/Unitronics Data Logs/'
[2022-08-17 20:06:04,461] {taskinstance.py:1420} INFO - Marking task as FAILED. dag_id=unitronics_ETL_v01, task_id=extract, execution_date=20220816T000000, start_date=20220817T200604, end_date=20220817T200604
[2022-08-17 20:06:04,474] {standard_task_runner.py:97} ERROR - Failed to execute job 57 for task extract ([Errno 2] No such file or directory: 'C:/Unitronics Data Logs/'; 1935)
[2022-08-17 20:06:04,492] {local_task_job.py:156} INFO - Task exited with return code 1
[2022-08-17 20:06:04,554] {local_task_job.py:273} INFO - 0 downstream tasks scheduled from follow-on schedule check
[2022-08-17 21:42:59,635] {taskinstance.py:1179} INFO - Dependencies all met for <TaskInstance: unitronics_ETL_v01.extract scheduled__2022-08-16T00:00:00+00:00 [queued]>
[2022-08-17 21:42:59,644] {taskinstance.py:1179} INFO - Dependencies all met for <TaskInstance: unitronics_ETL_v01.extract scheduled__2022-08-16T00:00:00+00:00 [queued]>
[2022-08-17 21:42:59,645] {taskinstance.py:1376} INFO - 
--------------------------------------------------------------------------------
[2022-08-17 21:42:59,645] {taskinstance.py:1377} INFO - Starting attempt 6 of 6
[2022-08-17 21:42:59,645] {taskinstance.py:1378} INFO - 
--------------------------------------------------------------------------------
[2022-08-17 21:42:59,659] {taskinstance.py:1397} INFO - Executing <Task(PythonOperator): extract> on 2022-08-16 00:00:00+00:00
[2022-08-17 21:42:59,664] {standard_task_runner.py:52} INFO - Started process 1798 to run task
[2022-08-17 21:42:59,671] {standard_task_runner.py:79} INFO - Running: ['***', 'tasks', 'run', 'unitronics_ETL_v01', 'extract', 'scheduled__2022-08-16T00:00:00+00:00', '--job-id', '26', '--raw', '--subdir', 'DAGS_FOLDER/unitronics_ETL.py', '--cfg-path', '/tmp/tmpv431d47x', '--error-file', '/tmp/tmpwpby31jl']
[2022-08-17 21:42:59,673] {standard_task_runner.py:80} INFO - Job 26: Subtask extract
[2022-08-17 21:42:59,741] {task_command.py:371} INFO - Running <TaskInstance: unitronics_ETL_v01.extract scheduled__2022-08-16T00:00:00+00:00 [running]> on host 1b0f89009e2c
[2022-08-17 21:42:59,815] {taskinstance.py:1591} INFO - Exporting the following env vars:
AIRFLOW_CTX_DAG_OWNER=Cavefish
AIRFLOW_CTX_DAG_ID=unitronics_ETL_v01
AIRFLOW_CTX_TASK_ID=extract
AIRFLOW_CTX_EXECUTION_DATE=2022-08-16T00:00:00+00:00
AIRFLOW_CTX_TRY_NUMBER=6
AIRFLOW_CTX_DAG_RUN_ID=scheduled__2022-08-16T00:00:00+00:00
[2022-08-17 21:42:59,824] {taskinstance.py:1909} ERROR - Task failed with exception
Traceback (most recent call last):
  File "/home/airflow/.local/lib/python3.7/site-packages/airflow/operators/python.py", line 171, in execute
    return_value = self.execute_callable()
  File "/home/airflow/.local/lib/python3.7/site-packages/airflow/operators/python.py", line 189, in execute_callable
    return self.python_callable(*self.op_args, **self.op_kwargs)
  File "/opt/airflow/dags/unitronics_ETL.py", line 76, in extractData
    files = os.listdir(dir_name)
FileNotFoundError: [Errno 2] No such file or directory: '/Unitronics Data Logs/'
[2022-08-17 21:42:59,835] {taskinstance.py:1420} INFO - Marking task as FAILED. dag_id=unitronics_ETL_v01, task_id=extract, execution_date=20220816T000000, start_date=20220817T214259, end_date=20220817T214259
[2022-08-17 21:42:59,845] {standard_task_runner.py:97} ERROR - Failed to execute job 26 for task extract ([Errno 2] No such file or directory: '/Unitronics Data Logs/'; 1798)
[2022-08-17 21:42:59,880] {local_task_job.py:156} INFO - Task exited with return code 1
[2022-08-17 21:43:00,007] {local_task_job.py:273} INFO - 0 downstream tasks scheduled from follow-on schedule check
