[2022-08-17 19:12:14,748] {taskinstance.py:1179} INFO - Dependencies all met for <TaskInstance: unitronics_ETL_v01.extract scheduled__2022-08-16T00:00:00+00:00 [queued]>
[2022-08-17 19:12:14,757] {taskinstance.py:1179} INFO - Dependencies all met for <TaskInstance: unitronics_ETL_v01.extract scheduled__2022-08-16T00:00:00+00:00 [queued]>
[2022-08-17 19:12:14,758] {taskinstance.py:1376} INFO - 
--------------------------------------------------------------------------------
[2022-08-17 19:12:14,758] {taskinstance.py:1377} INFO - Starting attempt 3 of 6
[2022-08-17 19:12:14,758] {taskinstance.py:1378} INFO - 
--------------------------------------------------------------------------------
[2022-08-17 19:12:14,773] {taskinstance.py:1397} INFO - Executing <Task(PythonOperator): extract> on 2022-08-16 00:00:00+00:00
[2022-08-17 19:12:14,777] {standard_task_runner.py:52} INFO - Started process 875 to run task
[2022-08-17 19:12:14,791] {standard_task_runner.py:79} INFO - Running: ['***', 'tasks', 'run', 'unitronics_ETL_v01', 'extract', 'scheduled__2022-08-16T00:00:00+00:00', '--job-id', '16', '--raw', '--subdir', 'DAGS_FOLDER/unitronics_ETL.py', '--cfg-path', '/tmp/tmpls6kukm_', '--error-file', '/tmp/tmpw4j4xoj1']
[2022-08-17 19:12:14,793] {standard_task_runner.py:80} INFO - Job 16: Subtask extract
[2022-08-17 19:12:14,868] {task_command.py:371} INFO - Running <TaskInstance: unitronics_ETL_v01.extract scheduled__2022-08-16T00:00:00+00:00 [running]> on host ea4c9b9e2e97
[2022-08-17 19:12:14,949] {taskinstance.py:1591} INFO - Exporting the following env vars:
AIRFLOW_CTX_DAG_OWNER=Cavefish
AIRFLOW_CTX_DAG_ID=unitronics_ETL_v01
AIRFLOW_CTX_TASK_ID=extract
AIRFLOW_CTX_EXECUTION_DATE=2022-08-16T00:00:00+00:00
AIRFLOW_CTX_TRY_NUMBER=3
AIRFLOW_CTX_DAG_RUN_ID=scheduled__2022-08-16T00:00:00+00:00
[2022-08-17 19:12:14,959] {taskinstance.py:1909} ERROR - Task failed with exception
Traceback (most recent call last):
  File "/home/airflow/.local/lib/python3.7/site-packages/airflow/operators/python.py", line 171, in execute
    return_value = self.execute_callable()
  File "/home/airflow/.local/lib/python3.7/site-packages/airflow/operators/python.py", line 189, in execute_callable
    return self.python_callable(*self.op_args, **self.op_kwargs)
  File "/opt/airflow/dags/unitronics_ETL.py", line 95, in extractData
    device_df = concatDataFrame(super_df_device)
  File "/opt/airflow/dags/unitronics_ETL.py", line 54, in concatDataFrame
    df = pd.concat(df, axis=0)
  File "/home/airflow/.local/lib/python3.7/site-packages/pandas/util/_decorators.py", line 311, in wrapper
    return func(*args, **kwargs)
  File "/home/airflow/.local/lib/python3.7/site-packages/pandas/core/reshape/concat.py", line 304, in concat
    sort=sort,
  File "/home/airflow/.local/lib/python3.7/site-packages/pandas/core/reshape/concat.py", line 351, in __init__
    raise ValueError("No objects to concatenate")
ValueError: No objects to concatenate
[2022-08-17 19:12:14,970] {taskinstance.py:1420} INFO - Marking task as UP_FOR_RETRY. dag_id=unitronics_ETL_v01, task_id=extract, execution_date=20220816T000000, start_date=20220817T191214, end_date=20220817T191214
[2022-08-17 19:12:14,980] {standard_task_runner.py:97} ERROR - Failed to execute job 16 for task extract (No objects to concatenate; 875)
[2022-08-17 19:12:14,998] {local_task_job.py:156} INFO - Task exited with return code 1
[2022-08-17 19:12:15,040] {local_task_job.py:273} INFO - 0 downstream tasks scheduled from follow-on schedule check
[2022-08-17 19:51:00,268] {taskinstance.py:1179} INFO - Dependencies all met for <TaskInstance: unitronics_ETL_v01.extract scheduled__2022-08-16T00:00:00+00:00 [queued]>
[2022-08-17 19:51:00,279] {taskinstance.py:1179} INFO - Dependencies all met for <TaskInstance: unitronics_ETL_v01.extract scheduled__2022-08-16T00:00:00+00:00 [queued]>
[2022-08-17 19:51:00,279] {taskinstance.py:1376} INFO - 
--------------------------------------------------------------------------------
[2022-08-17 19:51:00,279] {taskinstance.py:1377} INFO - Starting attempt 3 of 6
[2022-08-17 19:51:00,279] {taskinstance.py:1378} INFO - 
--------------------------------------------------------------------------------
[2022-08-17 19:51:00,298] {taskinstance.py:1397} INFO - Executing <Task(PythonOperator): extract> on 2022-08-16 00:00:00+00:00
[2022-08-17 19:51:00,303] {standard_task_runner.py:52} INFO - Started process 909 to run task
[2022-08-17 19:51:00,308] {standard_task_runner.py:79} INFO - Running: ['***', 'tasks', 'run', 'unitronics_ETL_v01', 'extract', 'scheduled__2022-08-16T00:00:00+00:00', '--job-id', '22', '--raw', '--subdir', 'DAGS_FOLDER/unitronics_ETL.py', '--cfg-path', '/tmp/tmpazptb1dd', '--error-file', '/tmp/tmp6_14hf54']
[2022-08-17 19:51:00,312] {standard_task_runner.py:80} INFO - Job 22: Subtask extract
[2022-08-17 19:51:00,392] {task_command.py:371} INFO - Running <TaskInstance: unitronics_ETL_v01.extract scheduled__2022-08-16T00:00:00+00:00 [running]> on host 8c93e37464e5
[2022-08-17 19:51:00,476] {taskinstance.py:1591} INFO - Exporting the following env vars:
AIRFLOW_CTX_DAG_OWNER=Cavefish
AIRFLOW_CTX_DAG_ID=unitronics_ETL_v01
AIRFLOW_CTX_TASK_ID=extract
AIRFLOW_CTX_EXECUTION_DATE=2022-08-16T00:00:00+00:00
AIRFLOW_CTX_TRY_NUMBER=3
AIRFLOW_CTX_DAG_RUN_ID=scheduled__2022-08-16T00:00:00+00:00
[2022-08-17 19:51:00,485] {taskinstance.py:1909} ERROR - Task failed with exception
Traceback (most recent call last):
  File "/home/airflow/.local/lib/python3.7/site-packages/airflow/operators/python.py", line 171, in execute
    return_value = self.execute_callable()
  File "/home/airflow/.local/lib/python3.7/site-packages/airflow/operators/python.py", line 189, in execute_callable
    return self.python_callable(*self.op_args, **self.op_kwargs)
  File "/opt/airflow/dags/unitronics_ETL.py", line 75, in extractData
    root, dirs, files = os.walk(dir_name)
ValueError: not enough values to unpack (expected 3, got 0)
[2022-08-17 19:51:00,496] {taskinstance.py:1420} INFO - Marking task as UP_FOR_RETRY. dag_id=unitronics_ETL_v01, task_id=extract, execution_date=20220816T000000, start_date=20220817T195100, end_date=20220817T195100
[2022-08-17 19:51:00,511] {standard_task_runner.py:97} ERROR - Failed to execute job 22 for task extract (not enough values to unpack (expected 3, got 0); 909)
[2022-08-17 19:51:00,520] {local_task_job.py:156} INFO - Task exited with return code 1
[2022-08-17 19:51:00,576] {local_task_job.py:273} INFO - 0 downstream tasks scheduled from follow-on schedule check
[2022-08-17 21:27:55,013] {taskinstance.py:1179} INFO - Dependencies all met for <TaskInstance: unitronics_ETL_v01.extract scheduled__2022-08-16T00:00:00+00:00 [queued]>
[2022-08-17 21:27:55,024] {taskinstance.py:1179} INFO - Dependencies all met for <TaskInstance: unitronics_ETL_v01.extract scheduled__2022-08-16T00:00:00+00:00 [queued]>
[2022-08-17 21:27:55,024] {taskinstance.py:1376} INFO - 
--------------------------------------------------------------------------------
[2022-08-17 21:27:55,024] {taskinstance.py:1377} INFO - Starting attempt 3 of 6
[2022-08-17 21:27:55,025] {taskinstance.py:1378} INFO - 
--------------------------------------------------------------------------------
[2022-08-17 21:27:55,041] {taskinstance.py:1397} INFO - Executing <Task(PythonOperator): extract> on 2022-08-16 00:00:00+00:00
[2022-08-17 21:27:55,049] {standard_task_runner.py:52} INFO - Started process 848 to run task
[2022-08-17 21:27:55,053] {standard_task_runner.py:79} INFO - Running: ['***', 'tasks', 'run', 'unitronics_ETL_v01', 'extract', 'scheduled__2022-08-16T00:00:00+00:00', '--job-id', '12', '--raw', '--subdir', 'DAGS_FOLDER/unitronics_ETL.py', '--cfg-path', '/tmp/tmphq8yn12u', '--error-file', '/tmp/tmp4s7kbvig']
[2022-08-17 21:27:55,054] {standard_task_runner.py:80} INFO - Job 12: Subtask extract
[2022-08-17 21:27:55,127] {task_command.py:371} INFO - Running <TaskInstance: unitronics_ETL_v01.extract scheduled__2022-08-16T00:00:00+00:00 [running]> on host 1b0f89009e2c
[2022-08-17 21:27:55,217] {taskinstance.py:1591} INFO - Exporting the following env vars:
AIRFLOW_CTX_DAG_OWNER=Cavefish
AIRFLOW_CTX_DAG_ID=unitronics_ETL_v01
AIRFLOW_CTX_TASK_ID=extract
AIRFLOW_CTX_EXECUTION_DATE=2022-08-16T00:00:00+00:00
AIRFLOW_CTX_TRY_NUMBER=3
AIRFLOW_CTX_DAG_RUN_ID=scheduled__2022-08-16T00:00:00+00:00
[2022-08-17 21:27:55,229] {taskinstance.py:1909} ERROR - Task failed with exception
Traceback (most recent call last):
  File "/home/airflow/.local/lib/python3.7/site-packages/airflow/operators/python.py", line 171, in execute
    return_value = self.execute_callable()
  File "/home/airflow/.local/lib/python3.7/site-packages/airflow/operators/python.py", line 189, in execute_callable
    return self.python_callable(*self.op_args, **self.op_kwargs)
  File "/opt/airflow/dags/unitronics_ETL.py", line 76, in extractData
    files = os.listdir(dir_name)
FileNotFoundError: [Errno 2] No such file or directory: '/Unitronics Data Logs/'
[2022-08-17 21:27:55,246] {taskinstance.py:1420} INFO - Marking task as UP_FOR_RETRY. dag_id=unitronics_ETL_v01, task_id=extract, execution_date=20220816T000000, start_date=20220817T212755, end_date=20220817T212755
[2022-08-17 21:27:55,274] {standard_task_runner.py:97} ERROR - Failed to execute job 12 for task extract ([Errno 2] No such file or directory: '/Unitronics Data Logs/'; 848)
[2022-08-17 21:27:55,310] {local_task_job.py:156} INFO - Task exited with return code 1
[2022-08-17 21:27:55,360] {local_task_job.py:273} INFO - 0 downstream tasks scheduled from follow-on schedule check
