[2022-08-17 19:17:16,418] {taskinstance.py:1179} INFO - Dependencies all met for <TaskInstance: unitronics_ETL_v01.extract scheduled__2022-08-16T00:00:00+00:00 [queued]>
[2022-08-17 19:17:16,427] {taskinstance.py:1179} INFO - Dependencies all met for <TaskInstance: unitronics_ETL_v01.extract scheduled__2022-08-16T00:00:00+00:00 [queued]>
[2022-08-17 19:17:16,427] {taskinstance.py:1376} INFO - 
--------------------------------------------------------------------------------
[2022-08-17 19:17:16,428] {taskinstance.py:1377} INFO - Starting attempt 4 of 6
[2022-08-17 19:17:16,428] {taskinstance.py:1378} INFO - 
--------------------------------------------------------------------------------
[2022-08-17 19:17:16,444] {taskinstance.py:1397} INFO - Executing <Task(PythonOperator): extract> on 2022-08-16 00:00:00+00:00
[2022-08-17 19:17:16,447] {standard_task_runner.py:52} INFO - Started process 1179 to run task
[2022-08-17 19:17:16,451] {standard_task_runner.py:79} INFO - Running: ['***', 'tasks', 'run', 'unitronics_ETL_v01', 'extract', 'scheduled__2022-08-16T00:00:00+00:00', '--job-id', '18', '--raw', '--subdir', 'DAGS_FOLDER/unitronics_ETL.py', '--cfg-path', '/tmp/tmpmxhi9lcs', '--error-file', '/tmp/tmpqdhptt4s']
[2022-08-17 19:17:16,452] {standard_task_runner.py:80} INFO - Job 18: Subtask extract
[2022-08-17 19:17:16,524] {task_command.py:371} INFO - Running <TaskInstance: unitronics_ETL_v01.extract scheduled__2022-08-16T00:00:00+00:00 [running]> on host ea4c9b9e2e97
[2022-08-17 19:17:16,600] {taskinstance.py:1591} INFO - Exporting the following env vars:
AIRFLOW_CTX_DAG_OWNER=Cavefish
AIRFLOW_CTX_DAG_ID=unitronics_ETL_v01
AIRFLOW_CTX_TASK_ID=extract
AIRFLOW_CTX_EXECUTION_DATE=2022-08-16T00:00:00+00:00
AIRFLOW_CTX_TRY_NUMBER=4
AIRFLOW_CTX_DAG_RUN_ID=scheduled__2022-08-16T00:00:00+00:00
[2022-08-17 19:17:16,609] {taskinstance.py:1909} ERROR - Task failed with exception
Traceback (most recent call last):
  File "/home/airflow/.local/lib/python3.7/site-packages/airflow/operators/python.py", line 171, in execute
    return_value = self.execute_callable()
  File "/home/airflow/.local/lib/python3.7/site-packages/airflow/operators/python.py", line 189, in execute_callable
    return self.python_callable(*self.op_args, **self.op_kwargs)
  File "/opt/airflow/dags/unitronics_ETL.py", line 95, in extractData
    device_df = concatDataFrame(super_df_device)
  File "/opt/airflow/dags/unitronics_ETL.py", line 54, in concatDataFrame
    df = pd.concat(df, axis=0)
  File "/home/airflow/.local/lib/python3.7/site-packages/pandas/util/_decorators.py", line 311, in wrapper
    return func(*args, **kwargs)
  File "/home/airflow/.local/lib/python3.7/site-packages/pandas/core/reshape/concat.py", line 304, in concat
    sort=sort,
  File "/home/airflow/.local/lib/python3.7/site-packages/pandas/core/reshape/concat.py", line 351, in __init__
    raise ValueError("No objects to concatenate")
ValueError: No objects to concatenate
[2022-08-17 19:17:16,620] {taskinstance.py:1420} INFO - Marking task as UP_FOR_RETRY. dag_id=unitronics_ETL_v01, task_id=extract, execution_date=20220816T000000, start_date=20220817T191716, end_date=20220817T191716
[2022-08-17 19:17:16,631] {standard_task_runner.py:97} ERROR - Failed to execute job 18 for task extract (No objects to concatenate; 1179)
[2022-08-17 19:17:16,665] {local_task_job.py:156} INFO - Task exited with return code 1
[2022-08-17 19:17:16,749] {local_task_job.py:273} INFO - 0 downstream tasks scheduled from follow-on schedule check
[2022-08-17 19:56:01,223] {taskinstance.py:1179} INFO - Dependencies all met for <TaskInstance: unitronics_ETL_v01.extract scheduled__2022-08-16T00:00:00+00:00 [queued]>
[2022-08-17 19:56:01,235] {taskinstance.py:1179} INFO - Dependencies all met for <TaskInstance: unitronics_ETL_v01.extract scheduled__2022-08-16T00:00:00+00:00 [queued]>
[2022-08-17 19:56:01,235] {taskinstance.py:1376} INFO - 
--------------------------------------------------------------------------------
[2022-08-17 19:56:01,236] {taskinstance.py:1377} INFO - Starting attempt 4 of 6
[2022-08-17 19:56:01,236] {taskinstance.py:1378} INFO - 
--------------------------------------------------------------------------------
[2022-08-17 19:56:01,254] {taskinstance.py:1397} INFO - Executing <Task(PythonOperator): extract> on 2022-08-16 00:00:00+00:00
[2022-08-17 19:56:01,260] {standard_task_runner.py:52} INFO - Started process 1242 to run task
[2022-08-17 19:56:01,267] {standard_task_runner.py:79} INFO - Running: ['***', 'tasks', 'run', 'unitronics_ETL_v01', 'extract', 'scheduled__2022-08-16T00:00:00+00:00', '--job-id', '29', '--raw', '--subdir', 'DAGS_FOLDER/unitronics_ETL.py', '--cfg-path', '/tmp/tmpy13ld9hr', '--error-file', '/tmp/tmpmpddhfn9']
[2022-08-17 19:56:01,269] {standard_task_runner.py:80} INFO - Job 29: Subtask extract
[2022-08-17 19:56:01,345] {task_command.py:371} INFO - Running <TaskInstance: unitronics_ETL_v01.extract scheduled__2022-08-16T00:00:00+00:00 [running]> on host 8c93e37464e5
[2022-08-17 19:56:01,430] {taskinstance.py:1591} INFO - Exporting the following env vars:
AIRFLOW_CTX_DAG_OWNER=Cavefish
AIRFLOW_CTX_DAG_ID=unitronics_ETL_v01
AIRFLOW_CTX_TASK_ID=extract
AIRFLOW_CTX_EXECUTION_DATE=2022-08-16T00:00:00+00:00
AIRFLOW_CTX_TRY_NUMBER=4
AIRFLOW_CTX_DAG_RUN_ID=scheduled__2022-08-16T00:00:00+00:00
[2022-08-17 19:56:01,438] {taskinstance.py:1909} ERROR - Task failed with exception
Traceback (most recent call last):
  File "/home/airflow/.local/lib/python3.7/site-packages/airflow/operators/python.py", line 171, in execute
    return_value = self.execute_callable()
  File "/home/airflow/.local/lib/python3.7/site-packages/airflow/operators/python.py", line 189, in execute_callable
    return self.python_callable(*self.op_args, **self.op_kwargs)
  File "/opt/airflow/dags/unitronics_ETL.py", line 75, in extractData
    files = os.listdir(dir_name)
FileNotFoundError: [Errno 2] No such file or directory: 'C:/Unitronics Data Logs'
[2022-08-17 19:56:01,450] {taskinstance.py:1420} INFO - Marking task as UP_FOR_RETRY. dag_id=unitronics_ETL_v01, task_id=extract, execution_date=20220816T000000, start_date=20220817T195601, end_date=20220817T195601
[2022-08-17 19:56:01,463] {standard_task_runner.py:97} ERROR - Failed to execute job 29 for task extract ([Errno 2] No such file or directory: 'C:/Unitronics Data Logs'; 1242)
[2022-08-17 19:56:01,480] {local_task_job.py:156} INFO - Task exited with return code 1
[2022-08-17 19:56:01,520] {local_task_job.py:273} INFO - 0 downstream tasks scheduled from follow-on schedule check
[2022-08-17 21:32:56,681] {taskinstance.py:1179} INFO - Dependencies all met for <TaskInstance: unitronics_ETL_v01.extract scheduled__2022-08-16T00:00:00+00:00 [queued]>
[2022-08-17 21:32:56,691] {taskinstance.py:1179} INFO - Dependencies all met for <TaskInstance: unitronics_ETL_v01.extract scheduled__2022-08-16T00:00:00+00:00 [queued]>
[2022-08-17 21:32:56,691] {taskinstance.py:1376} INFO - 
--------------------------------------------------------------------------------
[2022-08-17 21:32:56,691] {taskinstance.py:1377} INFO - Starting attempt 4 of 6
[2022-08-17 21:32:56,691] {taskinstance.py:1378} INFO - 
--------------------------------------------------------------------------------
[2022-08-17 21:32:56,707] {taskinstance.py:1397} INFO - Executing <Task(PythonOperator): extract> on 2022-08-16 00:00:00+00:00
[2022-08-17 21:32:56,711] {standard_task_runner.py:52} INFO - Started process 1160 to run task
[2022-08-17 21:32:56,714] {standard_task_runner.py:79} INFO - Running: ['***', 'tasks', 'run', 'unitronics_ETL_v01', 'extract', 'scheduled__2022-08-16T00:00:00+00:00', '--job-id', '15', '--raw', '--subdir', 'DAGS_FOLDER/unitronics_ETL.py', '--cfg-path', '/tmp/tmppjpsrl3e', '--error-file', '/tmp/tmpp4g5ws_5']
[2022-08-17 21:32:56,717] {standard_task_runner.py:80} INFO - Job 15: Subtask extract
[2022-08-17 21:32:56,789] {task_command.py:371} INFO - Running <TaskInstance: unitronics_ETL_v01.extract scheduled__2022-08-16T00:00:00+00:00 [running]> on host 1b0f89009e2c
[2022-08-17 21:32:56,870] {taskinstance.py:1591} INFO - Exporting the following env vars:
AIRFLOW_CTX_DAG_OWNER=Cavefish
AIRFLOW_CTX_DAG_ID=unitronics_ETL_v01
AIRFLOW_CTX_TASK_ID=extract
AIRFLOW_CTX_EXECUTION_DATE=2022-08-16T00:00:00+00:00
AIRFLOW_CTX_TRY_NUMBER=4
AIRFLOW_CTX_DAG_RUN_ID=scheduled__2022-08-16T00:00:00+00:00
[2022-08-17 21:32:56,878] {taskinstance.py:1909} ERROR - Task failed with exception
Traceback (most recent call last):
  File "/home/airflow/.local/lib/python3.7/site-packages/airflow/operators/python.py", line 171, in execute
    return_value = self.execute_callable()
  File "/home/airflow/.local/lib/python3.7/site-packages/airflow/operators/python.py", line 189, in execute_callable
    return self.python_callable(*self.op_args, **self.op_kwargs)
  File "/opt/airflow/dags/unitronics_ETL.py", line 76, in extractData
    files = os.listdir(dir_name)
FileNotFoundError: [Errno 2] No such file or directory: '/Unitronics Data Logs/'
[2022-08-17 21:32:56,895] {taskinstance.py:1420} INFO - Marking task as UP_FOR_RETRY. dag_id=unitronics_ETL_v01, task_id=extract, execution_date=20220816T000000, start_date=20220817T213256, end_date=20220817T213256
[2022-08-17 21:32:56,908] {standard_task_runner.py:97} ERROR - Failed to execute job 15 for task extract ([Errno 2] No such file or directory: '/Unitronics Data Logs/'; 1160)
[2022-08-17 21:32:56,926] {local_task_job.py:156} INFO - Task exited with return code 1
[2022-08-17 21:32:56,967] {local_task_job.py:273} INFO - 0 downstream tasks scheduled from follow-on schedule check
