[2022-08-17 21:32:56,694] {taskinstance.py:1179} INFO - Dependencies all met for <TaskInstance: unitronics_ETL_v01.extract manual__2022-08-17T21:17:49.954476+00:00 [queued]>
[2022-08-17 21:32:56,704] {taskinstance.py:1179} INFO - Dependencies all met for <TaskInstance: unitronics_ETL_v01.extract manual__2022-08-17T21:17:49.954476+00:00 [queued]>
[2022-08-17 21:32:56,704] {taskinstance.py:1376} INFO - 
--------------------------------------------------------------------------------
[2022-08-17 21:32:56,704] {taskinstance.py:1377} INFO - Starting attempt 4 of 6
[2022-08-17 21:32:56,705] {taskinstance.py:1378} INFO - 
--------------------------------------------------------------------------------
[2022-08-17 21:32:56,726] {taskinstance.py:1397} INFO - Executing <Task(PythonOperator): extract> on 2022-08-17 21:17:49.954476+00:00
[2022-08-17 21:32:56,730] {standard_task_runner.py:52} INFO - Started process 1163 to run task
[2022-08-17 21:32:56,733] {standard_task_runner.py:79} INFO - Running: ['***', 'tasks', 'run', 'unitronics_ETL_v01', 'extract', 'manual__2022-08-17T21:17:49.954476+00:00', '--job-id', '17', '--raw', '--subdir', 'DAGS_FOLDER/unitronics_ETL.py', '--cfg-path', '/tmp/tmpobpvd1rt', '--error-file', '/tmp/tmp_jt7hkpy']
[2022-08-17 21:32:56,734] {standard_task_runner.py:80} INFO - Job 17: Subtask extract
[2022-08-17 21:32:56,807] {task_command.py:371} INFO - Running <TaskInstance: unitronics_ETL_v01.extract manual__2022-08-17T21:17:49.954476+00:00 [running]> on host 1b0f89009e2c
[2022-08-17 21:32:56,890] {taskinstance.py:1591} INFO - Exporting the following env vars:
AIRFLOW_CTX_DAG_OWNER=Cavefish
AIRFLOW_CTX_DAG_ID=unitronics_ETL_v01
AIRFLOW_CTX_TASK_ID=extract
AIRFLOW_CTX_EXECUTION_DATE=2022-08-17T21:17:49.954476+00:00
AIRFLOW_CTX_TRY_NUMBER=4
AIRFLOW_CTX_DAG_RUN_ID=manual__2022-08-17T21:17:49.954476+00:00
[2022-08-17 21:32:56,899] {taskinstance.py:1909} ERROR - Task failed with exception
Traceback (most recent call last):
  File "/home/airflow/.local/lib/python3.7/site-packages/airflow/operators/python.py", line 171, in execute
    return_value = self.execute_callable()
  File "/home/airflow/.local/lib/python3.7/site-packages/airflow/operators/python.py", line 189, in execute_callable
    return self.python_callable(*self.op_args, **self.op_kwargs)
  File "/opt/airflow/dags/unitronics_ETL.py", line 76, in extractData
    files = os.listdir(dir_name)
FileNotFoundError: [Errno 2] No such file or directory: '/Unitronics Data Logs/'
[2022-08-17 21:32:56,909] {taskinstance.py:1420} INFO - Marking task as UP_FOR_RETRY. dag_id=unitronics_ETL_v01, task_id=extract, execution_date=20220817T211749, start_date=20220817T213256, end_date=20220817T213256
[2022-08-17 21:32:56,921] {standard_task_runner.py:97} ERROR - Failed to execute job 17 for task extract ([Errno 2] No such file or directory: '/Unitronics Data Logs/'; 1163)
[2022-08-17 21:32:56,945] {local_task_job.py:156} INFO - Task exited with return code 1
[2022-08-17 21:32:56,990] {local_task_job.py:273} INFO - 0 downstream tasks scheduled from follow-on schedule check
