[2022-08-17 21:22:53,181] {taskinstance.py:1179} INFO - Dependencies all met for <TaskInstance: unitronics_ETL_v01.extract manual__2022-08-17T21:17:49.954476+00:00 [queued]>
[2022-08-17 21:22:53,204] {taskinstance.py:1179} INFO - Dependencies all met for <TaskInstance: unitronics_ETL_v01.extract manual__2022-08-17T21:17:49.954476+00:00 [queued]>
[2022-08-17 21:22:53,205] {taskinstance.py:1376} INFO - 
--------------------------------------------------------------------------------
[2022-08-17 21:22:53,205] {taskinstance.py:1377} INFO - Starting attempt 2 of 6
[2022-08-17 21:22:53,206] {taskinstance.py:1378} INFO - 
--------------------------------------------------------------------------------
[2022-08-17 21:22:53,229] {taskinstance.py:1397} INFO - Executing <Task(PythonOperator): extract> on 2022-08-17 21:17:49.954476+00:00
[2022-08-17 21:22:53,234] {standard_task_runner.py:52} INFO - Started process 534 to run task
[2022-08-17 21:22:53,239] {standard_task_runner.py:79} INFO - Running: ['***', 'tasks', 'run', 'unitronics_ETL_v01', 'extract', 'manual__2022-08-17T21:17:49.954476+00:00', '--job-id', '10', '--raw', '--subdir', 'DAGS_FOLDER/unitronics_ETL.py', '--cfg-path', '/tmp/tmp375e7acc', '--error-file', '/tmp/tmpkt1jkl82']
[2022-08-17 21:22:53,240] {standard_task_runner.py:80} INFO - Job 10: Subtask extract
[2022-08-17 21:22:53,313] {task_command.py:371} INFO - Running <TaskInstance: unitronics_ETL_v01.extract manual__2022-08-17T21:17:49.954476+00:00 [running]> on host 1b0f89009e2c
[2022-08-17 21:22:53,403] {taskinstance.py:1591} INFO - Exporting the following env vars:
AIRFLOW_CTX_DAG_OWNER=Cavefish
AIRFLOW_CTX_DAG_ID=unitronics_ETL_v01
AIRFLOW_CTX_TASK_ID=extract
AIRFLOW_CTX_EXECUTION_DATE=2022-08-17T21:17:49.954476+00:00
AIRFLOW_CTX_TRY_NUMBER=2
AIRFLOW_CTX_DAG_RUN_ID=manual__2022-08-17T21:17:49.954476+00:00
[2022-08-17 21:22:53,412] {taskinstance.py:1909} ERROR - Task failed with exception
Traceback (most recent call last):
  File "/home/airflow/.local/lib/python3.7/site-packages/airflow/operators/python.py", line 171, in execute
    return_value = self.execute_callable()
  File "/home/airflow/.local/lib/python3.7/site-packages/airflow/operators/python.py", line 189, in execute_callable
    return self.python_callable(*self.op_args, **self.op_kwargs)
  File "/opt/airflow/dags/unitronics_ETL.py", line 76, in extractData
    files = os.listdir(dir_name)
FileNotFoundError: [Errno 2] No such file or directory: '/Unitronics Data Logs/'
[2022-08-17 21:22:53,422] {taskinstance.py:1420} INFO - Marking task as UP_FOR_RETRY. dag_id=unitronics_ETL_v01, task_id=extract, execution_date=20220817T211749, start_date=20220817T212253, end_date=20220817T212253
[2022-08-17 21:22:53,433] {standard_task_runner.py:97} ERROR - Failed to execute job 10 for task extract ([Errno 2] No such file or directory: '/Unitronics Data Logs/'; 534)
[2022-08-17 21:22:53,451] {local_task_job.py:156} INFO - Task exited with return code 1
[2022-08-17 21:22:53,496] {local_task_job.py:273} INFO - 0 downstream tasks scheduled from follow-on schedule check
