[2022-08-16 00:20:05,695] {taskinstance.py:1179} INFO - Dependencies all met for <TaskInstance: unitronics_ETL_v01.extract scheduled__2022-08-15T00:00:00+00:00 [queued]>
[2022-08-16 00:20:05,705] {taskinstance.py:1179} INFO - Dependencies all met for <TaskInstance: unitronics_ETL_v01.extract scheduled__2022-08-15T00:00:00+00:00 [queued]>
[2022-08-16 00:20:05,706] {taskinstance.py:1376} INFO - 
--------------------------------------------------------------------------------
[2022-08-16 00:20:05,706] {taskinstance.py:1377} INFO - Starting attempt 5 of 6
[2022-08-16 00:20:05,707] {taskinstance.py:1378} INFO - 
--------------------------------------------------------------------------------
[2022-08-16 00:20:05,720] {taskinstance.py:1397} INFO - Executing <Task(PythonOperator): extract> on 2022-08-15 00:00:00+00:00
[2022-08-16 00:20:05,725] {standard_task_runner.py:52} INFO - Started process 39561 to run task
[2022-08-16 00:20:05,727] {standard_task_runner.py:79} INFO - Running: ['***', 'tasks', 'run', 'unitronics_ETL_v01', 'extract', 'scheduled__2022-08-15T00:00:00+00:00', '--job-id', '17', '--raw', '--subdir', 'DAGS_FOLDER/unitronics_ETL.py', '--cfg-path', '/tmp/tmphnv7h_q2', '--error-file', '/tmp/tmp4izh4els']
[2022-08-16 00:20:05,729] {standard_task_runner.py:80} INFO - Job 17: Subtask extract
[2022-08-16 00:20:05,783] {task_command.py:371} INFO - Running <TaskInstance: unitronics_ETL_v01.extract scheduled__2022-08-15T00:00:00+00:00 [running]> on host 34b373f0486d
[2022-08-16 00:20:05,843] {taskinstance.py:1591} INFO - Exporting the following env vars:
AIRFLOW_CTX_DAG_OWNER=Cavefish
AIRFLOW_CTX_DAG_ID=unitronics_ETL_v01
AIRFLOW_CTX_TASK_ID=extract
AIRFLOW_CTX_EXECUTION_DATE=2022-08-15T00:00:00+00:00
AIRFLOW_CTX_TRY_NUMBER=5
AIRFLOW_CTX_DAG_RUN_ID=scheduled__2022-08-15T00:00:00+00:00
[2022-08-16 00:20:05,845] {taskinstance.py:1909} ERROR - Task failed with exception
Traceback (most recent call last):
  File "/home/airflow/.local/lib/python3.7/site-packages/airflow/operators/python.py", line 171, in execute
    return_value = self.execute_callable()
  File "/home/airflow/.local/lib/python3.7/site-packages/airflow/operators/python.py", line 189, in execute_callable
    return self.python_callable(*self.op_args, **self.op_kwargs)
TypeError: extractData() missing 1 required positional argument: 'dir_name'
[2022-08-16 00:20:05,854] {taskinstance.py:1420} INFO - Marking task as UP_FOR_RETRY. dag_id=unitronics_ETL_v01, task_id=extract, execution_date=20220815T000000, start_date=20220816T002005, end_date=20220816T002005
[2022-08-16 00:20:05,863] {standard_task_runner.py:97} ERROR - Failed to execute job 17 for task extract (extractData() missing 1 required positional argument: 'dir_name'; 39561)
[2022-08-16 00:20:05,900] {local_task_job.py:156} INFO - Task exited with return code 1
[2022-08-16 00:20:05,938] {local_task_job.py:273} INFO - 0 downstream tasks scheduled from follow-on schedule check
