[2022-08-16 00:05:03,063] {taskinstance.py:1179} INFO - Dependencies all met for <TaskInstance: unitronics_ETL_v01.extract scheduled__2022-08-15T00:00:00+00:00 [queued]>
[2022-08-16 00:05:03,072] {taskinstance.py:1179} INFO - Dependencies all met for <TaskInstance: unitronics_ETL_v01.extract scheduled__2022-08-15T00:00:00+00:00 [queued]>
[2022-08-16 00:05:03,073] {taskinstance.py:1376} INFO - 
--------------------------------------------------------------------------------
[2022-08-16 00:05:03,074] {taskinstance.py:1377} INFO - Starting attempt 2 of 6
[2022-08-16 00:05:03,074] {taskinstance.py:1378} INFO - 
--------------------------------------------------------------------------------
[2022-08-16 00:05:03,087] {taskinstance.py:1397} INFO - Executing <Task(PythonOperator): extract> on 2022-08-15 00:00:00+00:00
[2022-08-16 00:05:03,092] {standard_task_runner.py:52} INFO - Started process 38640 to run task
[2022-08-16 00:05:03,095] {standard_task_runner.py:79} INFO - Running: ['***', 'tasks', 'run', 'unitronics_ETL_v01', 'extract', 'scheduled__2022-08-15T00:00:00+00:00', '--job-id', '14', '--raw', '--subdir', 'DAGS_FOLDER/unitronics_ETL.py', '--cfg-path', '/tmp/tmps1rp5nm6', '--error-file', '/tmp/tmpeq8qihr2']
[2022-08-16 00:05:03,096] {standard_task_runner.py:80} INFO - Job 14: Subtask extract
[2022-08-16 00:05:03,149] {task_command.py:371} INFO - Running <TaskInstance: unitronics_ETL_v01.extract scheduled__2022-08-15T00:00:00+00:00 [running]> on host 34b373f0486d
[2022-08-16 00:05:03,211] {taskinstance.py:1591} INFO - Exporting the following env vars:
AIRFLOW_CTX_DAG_OWNER=Cavefish
AIRFLOW_CTX_DAG_ID=unitronics_ETL_v01
AIRFLOW_CTX_TASK_ID=extract
AIRFLOW_CTX_EXECUTION_DATE=2022-08-15T00:00:00+00:00
AIRFLOW_CTX_TRY_NUMBER=2
AIRFLOW_CTX_DAG_RUN_ID=scheduled__2022-08-15T00:00:00+00:00
[2022-08-16 00:05:03,212] {taskinstance.py:1909} ERROR - Task failed with exception
Traceback (most recent call last):
  File "/home/airflow/.local/lib/python3.7/site-packages/airflow/operators/python.py", line 171, in execute
    return_value = self.execute_callable()
  File "/home/airflow/.local/lib/python3.7/site-packages/airflow/operators/python.py", line 189, in execute_callable
    return self.python_callable(*self.op_args, **self.op_kwargs)
TypeError: extractData() missing 1 required positional argument: 'dir_name'
[2022-08-16 00:05:03,219] {taskinstance.py:1420} INFO - Marking task as UP_FOR_RETRY. dag_id=unitronics_ETL_v01, task_id=extract, execution_date=20220815T000000, start_date=20220816T000503, end_date=20220816T000503
[2022-08-16 00:05:03,229] {standard_task_runner.py:97} ERROR - Failed to execute job 14 for task extract (extractData() missing 1 required positional argument: 'dir_name'; 38640)
[2022-08-16 00:05:03,267] {local_task_job.py:156} INFO - Task exited with return code 1
[2022-08-16 00:05:03,307] {local_task_job.py:273} INFO - 0 downstream tasks scheduled from follow-on schedule check
