[2022-08-17 19:12:14,747] {taskinstance.py:1179} INFO - Dependencies all met for <TaskInstance: unitronics_ETL_v01.extract scheduled__2022-08-15T00:00:00+00:00 [queued]>
[2022-08-17 19:12:14,756] {taskinstance.py:1179} INFO - Dependencies all met for <TaskInstance: unitronics_ETL_v01.extract scheduled__2022-08-15T00:00:00+00:00 [queued]>
[2022-08-17 19:12:14,757] {taskinstance.py:1376} INFO - 
--------------------------------------------------------------------------------
[2022-08-17 19:12:14,757] {taskinstance.py:1377} INFO - Starting attempt 3 of 6
[2022-08-17 19:12:14,757] {taskinstance.py:1378} INFO - 
--------------------------------------------------------------------------------
[2022-08-17 19:12:14,772] {taskinstance.py:1397} INFO - Executing <Task(PythonOperator): extract> on 2022-08-15 00:00:00+00:00
[2022-08-17 19:12:14,777] {standard_task_runner.py:52} INFO - Started process 874 to run task
[2022-08-17 19:12:14,781] {standard_task_runner.py:79} INFO - Running: ['***', 'tasks', 'run', 'unitronics_ETL_v01', 'extract', 'scheduled__2022-08-15T00:00:00+00:00', '--job-id', '14', '--raw', '--subdir', 'DAGS_FOLDER/unitronics_ETL.py', '--cfg-path', '/tmp/tmp1chb21pp', '--error-file', '/tmp/tmp7vfzo6m8']
[2022-08-17 19:12:14,784] {standard_task_runner.py:80} INFO - Job 14: Subtask extract
[2022-08-17 19:12:14,859] {task_command.py:371} INFO - Running <TaskInstance: unitronics_ETL_v01.extract scheduled__2022-08-15T00:00:00+00:00 [running]> on host ea4c9b9e2e97
[2022-08-17 19:12:14,935] {taskinstance.py:1591} INFO - Exporting the following env vars:
AIRFLOW_CTX_DAG_OWNER=Cavefish
AIRFLOW_CTX_DAG_ID=unitronics_ETL_v01
AIRFLOW_CTX_TASK_ID=extract
AIRFLOW_CTX_EXECUTION_DATE=2022-08-15T00:00:00+00:00
AIRFLOW_CTX_TRY_NUMBER=3
AIRFLOW_CTX_DAG_RUN_ID=scheduled__2022-08-15T00:00:00+00:00
[2022-08-17 19:12:14,944] {taskinstance.py:1909} ERROR - Task failed with exception
Traceback (most recent call last):
  File "/home/airflow/.local/lib/python3.7/site-packages/airflow/operators/python.py", line 171, in execute
    return_value = self.execute_callable()
  File "/home/airflow/.local/lib/python3.7/site-packages/airflow/operators/python.py", line 189, in execute_callable
    return self.python_callable(*self.op_args, **self.op_kwargs)
  File "/opt/airflow/dags/unitronics_ETL.py", line 95, in extractData
    device_df = concatDataFrame(super_df_device)
  File "/opt/airflow/dags/unitronics_ETL.py", line 54, in concatDataFrame
    df = pd.concat(df, axis=0)
  File "/home/airflow/.local/lib/python3.7/site-packages/pandas/util/_decorators.py", line 311, in wrapper
    return func(*args, **kwargs)
  File "/home/airflow/.local/lib/python3.7/site-packages/pandas/core/reshape/concat.py", line 304, in concat
    sort=sort,
  File "/home/airflow/.local/lib/python3.7/site-packages/pandas/core/reshape/concat.py", line 351, in __init__
    raise ValueError("No objects to concatenate")
ValueError: No objects to concatenate
[2022-08-17 19:12:14,956] {taskinstance.py:1420} INFO - Marking task as UP_FOR_RETRY. dag_id=unitronics_ETL_v01, task_id=extract, execution_date=20220815T000000, start_date=20220817T191214, end_date=20220817T191214
[2022-08-17 19:12:14,967] {standard_task_runner.py:97} ERROR - Failed to execute job 14 for task extract (No objects to concatenate; 874)
[2022-08-17 19:12:14,994] {local_task_job.py:156} INFO - Task exited with return code 1
[2022-08-17 19:12:15,037] {local_task_job.py:273} INFO - 0 downstream tasks scheduled from follow-on schedule check
[2022-08-17 19:51:00,264] {taskinstance.py:1179} INFO - Dependencies all met for <TaskInstance: unitronics_ETL_v01.extract scheduled__2022-08-15T00:00:00+00:00 [queued]>
[2022-08-17 19:51:00,274] {taskinstance.py:1179} INFO - Dependencies all met for <TaskInstance: unitronics_ETL_v01.extract scheduled__2022-08-15T00:00:00+00:00 [queued]>
[2022-08-17 19:51:00,275] {taskinstance.py:1376} INFO - 
--------------------------------------------------------------------------------
[2022-08-17 19:51:00,275] {taskinstance.py:1377} INFO - Starting attempt 3 of 6
[2022-08-17 19:51:00,275] {taskinstance.py:1378} INFO - 
--------------------------------------------------------------------------------
[2022-08-17 19:51:00,293] {taskinstance.py:1397} INFO - Executing <Task(PythonOperator): extract> on 2022-08-15 00:00:00+00:00
[2022-08-17 19:51:00,297] {standard_task_runner.py:52} INFO - Started process 907 to run task
[2022-08-17 19:51:00,301] {standard_task_runner.py:79} INFO - Running: ['***', 'tasks', 'run', 'unitronics_ETL_v01', 'extract', 'scheduled__2022-08-15T00:00:00+00:00', '--job-id', '19', '--raw', '--subdir', 'DAGS_FOLDER/unitronics_ETL.py', '--cfg-path', '/tmp/tmpo87kzfnw', '--error-file', '/tmp/tmpklojf8ml']
[2022-08-17 19:51:00,302] {standard_task_runner.py:80} INFO - Job 19: Subtask extract
[2022-08-17 19:51:00,378] {task_command.py:371} INFO - Running <TaskInstance: unitronics_ETL_v01.extract scheduled__2022-08-15T00:00:00+00:00 [running]> on host 8c93e37464e5
[2022-08-17 19:51:00,463] {taskinstance.py:1591} INFO - Exporting the following env vars:
AIRFLOW_CTX_DAG_OWNER=Cavefish
AIRFLOW_CTX_DAG_ID=unitronics_ETL_v01
AIRFLOW_CTX_TASK_ID=extract
AIRFLOW_CTX_EXECUTION_DATE=2022-08-15T00:00:00+00:00
AIRFLOW_CTX_TRY_NUMBER=3
AIRFLOW_CTX_DAG_RUN_ID=scheduled__2022-08-15T00:00:00+00:00
[2022-08-17 19:51:00,472] {taskinstance.py:1909} ERROR - Task failed with exception
Traceback (most recent call last):
  File "/home/airflow/.local/lib/python3.7/site-packages/airflow/operators/python.py", line 171, in execute
    return_value = self.execute_callable()
  File "/home/airflow/.local/lib/python3.7/site-packages/airflow/operators/python.py", line 189, in execute_callable
    return self.python_callable(*self.op_args, **self.op_kwargs)
  File "/opt/airflow/dags/unitronics_ETL.py", line 75, in extractData
    root, dirs, files = os.walk(dir_name)
ValueError: not enough values to unpack (expected 3, got 0)
[2022-08-17 19:51:00,484] {taskinstance.py:1420} INFO - Marking task as UP_FOR_RETRY. dag_id=unitronics_ETL_v01, task_id=extract, execution_date=20220815T000000, start_date=20220817T195100, end_date=20220817T195100
[2022-08-17 19:51:00,498] {standard_task_runner.py:97} ERROR - Failed to execute job 19 for task extract (not enough values to unpack (expected 3, got 0); 907)
[2022-08-17 19:51:00,514] {local_task_job.py:156} INFO - Task exited with return code 1
[2022-08-17 19:51:00,562] {local_task_job.py:273} INFO - 0 downstream tasks scheduled from follow-on schedule check
[2022-08-17 21:27:55,017] {taskinstance.py:1179} INFO - Dependencies all met for <TaskInstance: unitronics_ETL_v01.extract scheduled__2022-08-15T00:00:00+00:00 [queued]>
[2022-08-17 21:27:55,031] {taskinstance.py:1179} INFO - Dependencies all met for <TaskInstance: unitronics_ETL_v01.extract scheduled__2022-08-15T00:00:00+00:00 [queued]>
[2022-08-17 21:27:55,031] {taskinstance.py:1376} INFO - 
--------------------------------------------------------------------------------
[2022-08-17 21:27:55,031] {taskinstance.py:1377} INFO - Starting attempt 3 of 6
[2022-08-17 21:27:55,031] {taskinstance.py:1378} INFO - 
--------------------------------------------------------------------------------
[2022-08-17 21:27:55,046] {taskinstance.py:1397} INFO - Executing <Task(PythonOperator): extract> on 2022-08-15 00:00:00+00:00
[2022-08-17 21:27:55,050] {standard_task_runner.py:52} INFO - Started process 849 to run task
[2022-08-17 21:27:55,060] {standard_task_runner.py:79} INFO - Running: ['***', 'tasks', 'run', 'unitronics_ETL_v01', 'extract', 'scheduled__2022-08-15T00:00:00+00:00', '--job-id', '11', '--raw', '--subdir', 'DAGS_FOLDER/unitronics_ETL.py', '--cfg-path', '/tmp/tmp_dflbj02', '--error-file', '/tmp/tmplyy07jv5']
[2022-08-17 21:27:55,062] {standard_task_runner.py:80} INFO - Job 11: Subtask extract
[2022-08-17 21:27:55,139] {task_command.py:371} INFO - Running <TaskInstance: unitronics_ETL_v01.extract scheduled__2022-08-15T00:00:00+00:00 [running]> on host 1b0f89009e2c
[2022-08-17 21:27:55,235] {taskinstance.py:1591} INFO - Exporting the following env vars:
AIRFLOW_CTX_DAG_OWNER=Cavefish
AIRFLOW_CTX_DAG_ID=unitronics_ETL_v01
AIRFLOW_CTX_TASK_ID=extract
AIRFLOW_CTX_EXECUTION_DATE=2022-08-15T00:00:00+00:00
AIRFLOW_CTX_TRY_NUMBER=3
AIRFLOW_CTX_DAG_RUN_ID=scheduled__2022-08-15T00:00:00+00:00
[2022-08-17 21:27:55,244] {taskinstance.py:1909} ERROR - Task failed with exception
Traceback (most recent call last):
  File "/home/airflow/.local/lib/python3.7/site-packages/airflow/operators/python.py", line 171, in execute
    return_value = self.execute_callable()
  File "/home/airflow/.local/lib/python3.7/site-packages/airflow/operators/python.py", line 189, in execute_callable
    return self.python_callable(*self.op_args, **self.op_kwargs)
  File "/opt/airflow/dags/unitronics_ETL.py", line 76, in extractData
    files = os.listdir(dir_name)
FileNotFoundError: [Errno 2] No such file or directory: '/Unitronics Data Logs/'
[2022-08-17 21:27:55,260] {taskinstance.py:1420} INFO - Marking task as UP_FOR_RETRY. dag_id=unitronics_ETL_v01, task_id=extract, execution_date=20220815T000000, start_date=20220817T212755, end_date=20220817T212755
[2022-08-17 21:27:55,281] {standard_task_runner.py:97} ERROR - Failed to execute job 11 for task extract ([Errno 2] No such file or directory: '/Unitronics Data Logs/'; 849)
[2022-08-17 21:27:55,307] {local_task_job.py:156} INFO - Task exited with return code 1
[2022-08-17 21:27:55,355] {local_task_job.py:273} INFO - 0 downstream tasks scheduled from follow-on schedule check
