[2022-08-17 19:22:17,657] {taskinstance.py:1179} INFO - Dependencies all met for <TaskInstance: unitronics_ETL_v01.extract scheduled__2022-08-15T00:00:00+00:00 [queued]>
[2022-08-17 19:22:17,684] {taskinstance.py:1179} INFO - Dependencies all met for <TaskInstance: unitronics_ETL_v01.extract scheduled__2022-08-15T00:00:00+00:00 [queued]>
[2022-08-17 19:22:17,684] {taskinstance.py:1376} INFO - 
--------------------------------------------------------------------------------
[2022-08-17 19:22:17,684] {taskinstance.py:1377} INFO - Starting attempt 5 of 6
[2022-08-17 19:22:17,685] {taskinstance.py:1378} INFO - 
--------------------------------------------------------------------------------
[2022-08-17 19:22:17,714] {taskinstance.py:1397} INFO - Executing <Task(PythonOperator): extract> on 2022-08-15 00:00:00+00:00
[2022-08-17 19:22:17,718] {standard_task_runner.py:52} INFO - Started process 1515 to run task
[2022-08-17 19:22:17,726] {standard_task_runner.py:79} INFO - Running: ['***', 'tasks', 'run', 'unitronics_ETL_v01', 'extract', 'scheduled__2022-08-15T00:00:00+00:00', '--job-id', '28', '--raw', '--subdir', 'DAGS_FOLDER/unitronics_ETL.py', '--cfg-path', '/tmp/tmpruwik8uv', '--error-file', '/tmp/tmpwm96sbhb']
[2022-08-17 19:22:17,727] {standard_task_runner.py:80} INFO - Job 28: Subtask extract
[2022-08-17 19:22:17,920] {task_command.py:371} INFO - Running <TaskInstance: unitronics_ETL_v01.extract scheduled__2022-08-15T00:00:00+00:00 [running]> on host ea4c9b9e2e97
[2022-08-17 19:22:18,048] {taskinstance.py:1591} INFO - Exporting the following env vars:
AIRFLOW_CTX_DAG_OWNER=Cavefish
AIRFLOW_CTX_DAG_ID=unitronics_ETL_v01
AIRFLOW_CTX_TASK_ID=extract
AIRFLOW_CTX_EXECUTION_DATE=2022-08-15T00:00:00+00:00
AIRFLOW_CTX_TRY_NUMBER=5
AIRFLOW_CTX_DAG_RUN_ID=scheduled__2022-08-15T00:00:00+00:00
[2022-08-17 19:22:18,056] {taskinstance.py:1909} ERROR - Task failed with exception
Traceback (most recent call last):
  File "/home/airflow/.local/lib/python3.7/site-packages/airflow/operators/python.py", line 171, in execute
    return_value = self.execute_callable()
  File "/home/airflow/.local/lib/python3.7/site-packages/airflow/operators/python.py", line 189, in execute_callable
    return self.python_callable(*self.op_args, **self.op_kwargs)
  File "/opt/airflow/dags/unitronics_ETL.py", line 95, in extractData
    device_df = concatDataFrame(super_df_device)
  File "/opt/airflow/dags/unitronics_ETL.py", line 54, in concatDataFrame
    df = pd.concat(df, axis=0)
  File "/home/airflow/.local/lib/python3.7/site-packages/pandas/util/_decorators.py", line 311, in wrapper
    return func(*args, **kwargs)
  File "/home/airflow/.local/lib/python3.7/site-packages/pandas/core/reshape/concat.py", line 304, in concat
    sort=sort,
  File "/home/airflow/.local/lib/python3.7/site-packages/pandas/core/reshape/concat.py", line 351, in __init__
    raise ValueError("No objects to concatenate")
ValueError: No objects to concatenate
[2022-08-17 19:22:18,068] {taskinstance.py:1420} INFO - Marking task as UP_FOR_RETRY. dag_id=unitronics_ETL_v01, task_id=extract, execution_date=20220815T000000, start_date=20220817T192217, end_date=20220817T192218
[2022-08-17 19:22:18,081] {standard_task_runner.py:97} ERROR - Failed to execute job 28 for task extract (No objects to concatenate; 1515)
[2022-08-17 19:22:18,096] {local_task_job.py:156} INFO - Task exited with return code 1
[2022-08-17 19:22:18,192] {local_task_job.py:273} INFO - 0 downstream tasks scheduled from follow-on schedule check
[2022-08-17 20:01:03,133] {taskinstance.py:1179} INFO - Dependencies all met for <TaskInstance: unitronics_ETL_v01.extract scheduled__2022-08-15T00:00:00+00:00 [queued]>
[2022-08-17 20:01:03,142] {taskinstance.py:1179} INFO - Dependencies all met for <TaskInstance: unitronics_ETL_v01.extract scheduled__2022-08-15T00:00:00+00:00 [queued]>
[2022-08-17 20:01:03,143] {taskinstance.py:1376} INFO - 
--------------------------------------------------------------------------------
[2022-08-17 20:01:03,143] {taskinstance.py:1377} INFO - Starting attempt 5 of 6
[2022-08-17 20:01:03,143] {taskinstance.py:1378} INFO - 
--------------------------------------------------------------------------------
[2022-08-17 20:01:03,166] {taskinstance.py:1397} INFO - Executing <Task(PythonOperator): extract> on 2022-08-15 00:00:00+00:00
[2022-08-17 20:01:03,171] {standard_task_runner.py:52} INFO - Started process 1600 to run task
[2022-08-17 20:01:03,183] {standard_task_runner.py:79} INFO - Running: ['***', 'tasks', 'run', 'unitronics_ETL_v01', 'extract', 'scheduled__2022-08-15T00:00:00+00:00', '--job-id', '41', '--raw', '--subdir', 'DAGS_FOLDER/unitronics_ETL.py', '--cfg-path', '/tmp/tmpj233e26c', '--error-file', '/tmp/tmpj3w_aspn']
[2022-08-17 20:01:03,185] {standard_task_runner.py:80} INFO - Job 41: Subtask extract
[2022-08-17 20:01:03,255] {task_command.py:371} INFO - Running <TaskInstance: unitronics_ETL_v01.extract scheduled__2022-08-15T00:00:00+00:00 [running]> on host 8c93e37464e5
[2022-08-17 20:01:03,335] {taskinstance.py:1591} INFO - Exporting the following env vars:
AIRFLOW_CTX_DAG_OWNER=Cavefish
AIRFLOW_CTX_DAG_ID=unitronics_ETL_v01
AIRFLOW_CTX_TASK_ID=extract
AIRFLOW_CTX_EXECUTION_DATE=2022-08-15T00:00:00+00:00
AIRFLOW_CTX_TRY_NUMBER=5
AIRFLOW_CTX_DAG_RUN_ID=scheduled__2022-08-15T00:00:00+00:00
[2022-08-17 20:01:03,346] {taskinstance.py:1909} ERROR - Task failed with exception
Traceback (most recent call last):
  File "/home/airflow/.local/lib/python3.7/site-packages/airflow/operators/python.py", line 171, in execute
    return_value = self.execute_callable()
  File "/home/airflow/.local/lib/python3.7/site-packages/airflow/operators/python.py", line 189, in execute_callable
    return self.python_callable(*self.op_args, **self.op_kwargs)
  File "/opt/airflow/dags/unitronics_ETL.py", line 75, in extractData
    files = os.listdir(dir_name)
FileNotFoundError: [Errno 2] No such file or directory: 'C:/Unitronics Data Logs/'
[2022-08-17 20:01:03,361] {taskinstance.py:1420} INFO - Marking task as UP_FOR_RETRY. dag_id=unitronics_ETL_v01, task_id=extract, execution_date=20220815T000000, start_date=20220817T200103, end_date=20220817T200103
[2022-08-17 20:01:03,373] {standard_task_runner.py:97} ERROR - Failed to execute job 41 for task extract ([Errno 2] No such file or directory: 'C:/Unitronics Data Logs/'; 1600)
[2022-08-17 20:01:03,391] {local_task_job.py:156} INFO - Task exited with return code 1
[2022-08-17 20:01:03,466] {local_task_job.py:273} INFO - 0 downstream tasks scheduled from follow-on schedule check
[2022-08-17 21:37:58,238] {taskinstance.py:1179} INFO - Dependencies all met for <TaskInstance: unitronics_ETL_v01.extract scheduled__2022-08-15T00:00:00+00:00 [queued]>
[2022-08-17 21:37:58,249] {taskinstance.py:1179} INFO - Dependencies all met for <TaskInstance: unitronics_ETL_v01.extract scheduled__2022-08-15T00:00:00+00:00 [queued]>
[2022-08-17 21:37:58,250] {taskinstance.py:1376} INFO - 
--------------------------------------------------------------------------------
[2022-08-17 21:37:58,250] {taskinstance.py:1377} INFO - Starting attempt 5 of 6
[2022-08-17 21:37:58,250] {taskinstance.py:1378} INFO - 
--------------------------------------------------------------------------------
[2022-08-17 21:37:58,266] {taskinstance.py:1397} INFO - Executing <Task(PythonOperator): extract> on 2022-08-15 00:00:00+00:00
[2022-08-17 21:37:58,270] {standard_task_runner.py:52} INFO - Started process 1475 to run task
[2022-08-17 21:37:58,274] {standard_task_runner.py:79} INFO - Running: ['***', 'tasks', 'run', 'unitronics_ETL_v01', 'extract', 'scheduled__2022-08-15T00:00:00+00:00', '--job-id', '19', '--raw', '--subdir', 'DAGS_FOLDER/unitronics_ETL.py', '--cfg-path', '/tmp/tmpc4gukvv4', '--error-file', '/tmp/tmp84tntia_']
[2022-08-17 21:37:58,275] {standard_task_runner.py:80} INFO - Job 19: Subtask extract
[2022-08-17 21:37:58,350] {task_command.py:371} INFO - Running <TaskInstance: unitronics_ETL_v01.extract scheduled__2022-08-15T00:00:00+00:00 [running]> on host 1b0f89009e2c
[2022-08-17 21:37:58,433] {taskinstance.py:1591} INFO - Exporting the following env vars:
AIRFLOW_CTX_DAG_OWNER=Cavefish
AIRFLOW_CTX_DAG_ID=unitronics_ETL_v01
AIRFLOW_CTX_TASK_ID=extract
AIRFLOW_CTX_EXECUTION_DATE=2022-08-15T00:00:00+00:00
AIRFLOW_CTX_TRY_NUMBER=5
AIRFLOW_CTX_DAG_RUN_ID=scheduled__2022-08-15T00:00:00+00:00
[2022-08-17 21:37:58,442] {taskinstance.py:1909} ERROR - Task failed with exception
Traceback (most recent call last):
  File "/home/airflow/.local/lib/python3.7/site-packages/airflow/operators/python.py", line 171, in execute
    return_value = self.execute_callable()
  File "/home/airflow/.local/lib/python3.7/site-packages/airflow/operators/python.py", line 189, in execute_callable
    return self.python_callable(*self.op_args, **self.op_kwargs)
  File "/opt/airflow/dags/unitronics_ETL.py", line 76, in extractData
    files = os.listdir(dir_name)
FileNotFoundError: [Errno 2] No such file or directory: '/Unitronics Data Logs/'
[2022-08-17 21:37:58,453] {taskinstance.py:1420} INFO - Marking task as UP_FOR_RETRY. dag_id=unitronics_ETL_v01, task_id=extract, execution_date=20220815T000000, start_date=20220817T213758, end_date=20220817T213758
[2022-08-17 21:37:58,466] {standard_task_runner.py:97} ERROR - Failed to execute job 19 for task extract ([Errno 2] No such file or directory: '/Unitronics Data Logs/'; 1475)
[2022-08-17 21:37:58,487] {local_task_job.py:156} INFO - Task exited with return code 1
[2022-08-17 21:37:58,569] {local_task_job.py:273} INFO - 0 downstream tasks scheduled from follow-on schedule check
