[2022-08-17 19:12:14,739] {taskinstance.py:1179} INFO - Dependencies all met for <TaskInstance: unitronics_ETL_v01.extract scheduled__2022-08-14T00:00:00+00:00 [queued]>
[2022-08-17 19:12:14,748] {taskinstance.py:1179} INFO - Dependencies all met for <TaskInstance: unitronics_ETL_v01.extract scheduled__2022-08-14T00:00:00+00:00 [queued]>
[2022-08-17 19:12:14,749] {taskinstance.py:1376} INFO - 
--------------------------------------------------------------------------------
[2022-08-17 19:12:14,749] {taskinstance.py:1377} INFO - Starting attempt 3 of 6
[2022-08-17 19:12:14,749] {taskinstance.py:1378} INFO - 
--------------------------------------------------------------------------------
[2022-08-17 19:12:14,763] {taskinstance.py:1397} INFO - Executing <Task(PythonOperator): extract> on 2022-08-14 00:00:00+00:00
[2022-08-17 19:12:14,767] {standard_task_runner.py:52} INFO - Started process 873 to run task
[2022-08-17 19:12:14,771] {standard_task_runner.py:79} INFO - Running: ['***', 'tasks', 'run', 'unitronics_ETL_v01', 'extract', 'scheduled__2022-08-14T00:00:00+00:00', '--job-id', '13', '--raw', '--subdir', 'DAGS_FOLDER/unitronics_ETL.py', '--cfg-path', '/tmp/tmpff6y7jh_', '--error-file', '/tmp/tmp67uel2b8']
[2022-08-17 19:12:14,772] {standard_task_runner.py:80} INFO - Job 13: Subtask extract
[2022-08-17 19:12:14,852] {task_command.py:371} INFO - Running <TaskInstance: unitronics_ETL_v01.extract scheduled__2022-08-14T00:00:00+00:00 [running]> on host ea4c9b9e2e97
[2022-08-17 19:12:14,930] {taskinstance.py:1591} INFO - Exporting the following env vars:
AIRFLOW_CTX_DAG_OWNER=Cavefish
AIRFLOW_CTX_DAG_ID=unitronics_ETL_v01
AIRFLOW_CTX_TASK_ID=extract
AIRFLOW_CTX_EXECUTION_DATE=2022-08-14T00:00:00+00:00
AIRFLOW_CTX_TRY_NUMBER=3
AIRFLOW_CTX_DAG_RUN_ID=scheduled__2022-08-14T00:00:00+00:00
[2022-08-17 19:12:14,939] {taskinstance.py:1909} ERROR - Task failed with exception
Traceback (most recent call last):
  File "/home/airflow/.local/lib/python3.7/site-packages/airflow/operators/python.py", line 171, in execute
    return_value = self.execute_callable()
  File "/home/airflow/.local/lib/python3.7/site-packages/airflow/operators/python.py", line 189, in execute_callable
    return self.python_callable(*self.op_args, **self.op_kwargs)
  File "/opt/airflow/dags/unitronics_ETL.py", line 95, in extractData
    device_df = concatDataFrame(super_df_device)
  File "/opt/airflow/dags/unitronics_ETL.py", line 54, in concatDataFrame
    df = pd.concat(df, axis=0)
  File "/home/airflow/.local/lib/python3.7/site-packages/pandas/util/_decorators.py", line 311, in wrapper
    return func(*args, **kwargs)
  File "/home/airflow/.local/lib/python3.7/site-packages/pandas/core/reshape/concat.py", line 304, in concat
    sort=sort,
  File "/home/airflow/.local/lib/python3.7/site-packages/pandas/core/reshape/concat.py", line 351, in __init__
    raise ValueError("No objects to concatenate")
ValueError: No objects to concatenate
[2022-08-17 19:12:14,950] {taskinstance.py:1420} INFO - Marking task as UP_FOR_RETRY. dag_id=unitronics_ETL_v01, task_id=extract, execution_date=20220814T000000, start_date=20220817T191214, end_date=20220817T191214
[2022-08-17 19:12:14,962] {standard_task_runner.py:97} ERROR - Failed to execute job 13 for task extract (No objects to concatenate; 873)
[2022-08-17 19:12:14,983] {local_task_job.py:156} INFO - Task exited with return code 1
[2022-08-17 19:12:15,025] {local_task_job.py:273} INFO - 0 downstream tasks scheduled from follow-on schedule check
[2022-08-17 19:51:00,266] {taskinstance.py:1179} INFO - Dependencies all met for <TaskInstance: unitronics_ETL_v01.extract scheduled__2022-08-14T00:00:00+00:00 [queued]>
[2022-08-17 19:51:00,277] {taskinstance.py:1179} INFO - Dependencies all met for <TaskInstance: unitronics_ETL_v01.extract scheduled__2022-08-14T00:00:00+00:00 [queued]>
[2022-08-17 19:51:00,278] {taskinstance.py:1376} INFO - 
--------------------------------------------------------------------------------
[2022-08-17 19:51:00,278] {taskinstance.py:1377} INFO - Starting attempt 3 of 6
[2022-08-17 19:51:00,278] {taskinstance.py:1378} INFO - 
--------------------------------------------------------------------------------
[2022-08-17 19:51:00,298] {taskinstance.py:1397} INFO - Executing <Task(PythonOperator): extract> on 2022-08-14 00:00:00+00:00
[2022-08-17 19:51:00,303] {standard_task_runner.py:52} INFO - Started process 910 to run task
[2022-08-17 19:51:00,310] {standard_task_runner.py:79} INFO - Running: ['***', 'tasks', 'run', 'unitronics_ETL_v01', 'extract', 'scheduled__2022-08-14T00:00:00+00:00', '--job-id', '20', '--raw', '--subdir', 'DAGS_FOLDER/unitronics_ETL.py', '--cfg-path', '/tmp/tmp_gvdem09', '--error-file', '/tmp/tmpxek_5ntd']
[2022-08-17 19:51:00,312] {standard_task_runner.py:80} INFO - Job 20: Subtask extract
[2022-08-17 19:51:00,397] {task_command.py:371} INFO - Running <TaskInstance: unitronics_ETL_v01.extract scheduled__2022-08-14T00:00:00+00:00 [running]> on host 8c93e37464e5
[2022-08-17 19:51:00,489] {taskinstance.py:1591} INFO - Exporting the following env vars:
AIRFLOW_CTX_DAG_OWNER=Cavefish
AIRFLOW_CTX_DAG_ID=unitronics_ETL_v01
AIRFLOW_CTX_TASK_ID=extract
AIRFLOW_CTX_EXECUTION_DATE=2022-08-14T00:00:00+00:00
AIRFLOW_CTX_TRY_NUMBER=3
AIRFLOW_CTX_DAG_RUN_ID=scheduled__2022-08-14T00:00:00+00:00
[2022-08-17 19:51:00,498] {taskinstance.py:1909} ERROR - Task failed with exception
Traceback (most recent call last):
  File "/home/airflow/.local/lib/python3.7/site-packages/airflow/operators/python.py", line 171, in execute
    return_value = self.execute_callable()
  File "/home/airflow/.local/lib/python3.7/site-packages/airflow/operators/python.py", line 189, in execute_callable
    return self.python_callable(*self.op_args, **self.op_kwargs)
  File "/opt/airflow/dags/unitronics_ETL.py", line 75, in extractData
    root, dirs, files = os.walk(dir_name)
ValueError: not enough values to unpack (expected 3, got 0)
[2022-08-17 19:51:00,509] {taskinstance.py:1420} INFO - Marking task as UP_FOR_RETRY. dag_id=unitronics_ETL_v01, task_id=extract, execution_date=20220814T000000, start_date=20220817T195100, end_date=20220817T195100
[2022-08-17 19:51:00,524] {standard_task_runner.py:97} ERROR - Failed to execute job 20 for task extract (not enough values to unpack (expected 3, got 0); 910)
[2022-08-17 19:51:00,559] {local_task_job.py:156} INFO - Task exited with return code 1
[2022-08-17 19:51:00,644] {local_task_job.py:273} INFO - 0 downstream tasks scheduled from follow-on schedule check
[2022-08-17 21:27:55,050] {taskinstance.py:1179} INFO - Dependencies all met for <TaskInstance: unitronics_ETL_v01.extract scheduled__2022-08-14T00:00:00+00:00 [queued]>
[2022-08-17 21:27:55,064] {taskinstance.py:1179} INFO - Dependencies all met for <TaskInstance: unitronics_ETL_v01.extract scheduled__2022-08-14T00:00:00+00:00 [queued]>
[2022-08-17 21:27:55,064] {taskinstance.py:1376} INFO - 
--------------------------------------------------------------------------------
[2022-08-17 21:27:55,065] {taskinstance.py:1377} INFO - Starting attempt 3 of 6
[2022-08-17 21:27:55,065] {taskinstance.py:1378} INFO - 
--------------------------------------------------------------------------------
[2022-08-17 21:27:55,108] {taskinstance.py:1397} INFO - Executing <Task(PythonOperator): extract> on 2022-08-14 00:00:00+00:00
[2022-08-17 21:27:55,115] {standard_task_runner.py:52} INFO - Started process 851 to run task
[2022-08-17 21:27:55,119] {standard_task_runner.py:79} INFO - Running: ['***', 'tasks', 'run', 'unitronics_ETL_v01', 'extract', 'scheduled__2022-08-14T00:00:00+00:00', '--job-id', '13', '--raw', '--subdir', 'DAGS_FOLDER/unitronics_ETL.py', '--cfg-path', '/tmp/tmpxha18bit', '--error-file', '/tmp/tmpai00rufp']
[2022-08-17 21:27:55,120] {standard_task_runner.py:80} INFO - Job 13: Subtask extract
[2022-08-17 21:27:55,201] {task_command.py:371} INFO - Running <TaskInstance: unitronics_ETL_v01.extract scheduled__2022-08-14T00:00:00+00:00 [running]> on host 1b0f89009e2c
[2022-08-17 21:27:55,299] {taskinstance.py:1591} INFO - Exporting the following env vars:
AIRFLOW_CTX_DAG_OWNER=Cavefish
AIRFLOW_CTX_DAG_ID=unitronics_ETL_v01
AIRFLOW_CTX_TASK_ID=extract
AIRFLOW_CTX_EXECUTION_DATE=2022-08-14T00:00:00+00:00
AIRFLOW_CTX_TRY_NUMBER=3
AIRFLOW_CTX_DAG_RUN_ID=scheduled__2022-08-14T00:00:00+00:00
[2022-08-17 21:27:55,308] {taskinstance.py:1909} ERROR - Task failed with exception
Traceback (most recent call last):
  File "/home/airflow/.local/lib/python3.7/site-packages/airflow/operators/python.py", line 171, in execute
    return_value = self.execute_callable()
  File "/home/airflow/.local/lib/python3.7/site-packages/airflow/operators/python.py", line 189, in execute_callable
    return self.python_callable(*self.op_args, **self.op_kwargs)
  File "/opt/airflow/dags/unitronics_ETL.py", line 76, in extractData
    files = os.listdir(dir_name)
FileNotFoundError: [Errno 2] No such file or directory: '/Unitronics Data Logs/'
[2022-08-17 21:27:55,319] {taskinstance.py:1420} INFO - Marking task as UP_FOR_RETRY. dag_id=unitronics_ETL_v01, task_id=extract, execution_date=20220814T000000, start_date=20220817T212755, end_date=20220817T212755
[2022-08-17 21:27:55,334] {standard_task_runner.py:97} ERROR - Failed to execute job 13 for task extract ([Errno 2] No such file or directory: '/Unitronics Data Logs/'; 851)
[2022-08-17 21:27:55,378] {local_task_job.py:156} INFO - Task exited with return code 1
[2022-08-17 21:27:55,421] {local_task_job.py:273} INFO - 0 downstream tasks scheduled from follow-on schedule check
