[2022-08-17 19:17:16,422] {taskinstance.py:1179} INFO - Dependencies all met for <TaskInstance: unitronics_ETL_v01.extract scheduled__2022-08-14T00:00:00+00:00 [queued]>
[2022-08-17 19:17:16,431] {taskinstance.py:1179} INFO - Dependencies all met for <TaskInstance: unitronics_ETL_v01.extract scheduled__2022-08-14T00:00:00+00:00 [queued]>
[2022-08-17 19:17:16,432] {taskinstance.py:1376} INFO - 
--------------------------------------------------------------------------------
[2022-08-17 19:17:16,432] {taskinstance.py:1377} INFO - Starting attempt 4 of 6
[2022-08-17 19:17:16,433] {taskinstance.py:1378} INFO - 
--------------------------------------------------------------------------------
[2022-08-17 19:17:16,449] {taskinstance.py:1397} INFO - Executing <Task(PythonOperator): extract> on 2022-08-14 00:00:00+00:00
[2022-08-17 19:17:16,453] {standard_task_runner.py:52} INFO - Started process 1181 to run task
[2022-08-17 19:17:16,460] {standard_task_runner.py:79} INFO - Running: ['***', 'tasks', 'run', 'unitronics_ETL_v01', 'extract', 'scheduled__2022-08-14T00:00:00+00:00', '--job-id', '20', '--raw', '--subdir', 'DAGS_FOLDER/unitronics_ETL.py', '--cfg-path', '/tmp/tmp_9b11qmk', '--error-file', '/tmp/tmp3tv0ifot']
[2022-08-17 19:17:16,461] {standard_task_runner.py:80} INFO - Job 20: Subtask extract
[2022-08-17 19:17:16,530] {task_command.py:371} INFO - Running <TaskInstance: unitronics_ETL_v01.extract scheduled__2022-08-14T00:00:00+00:00 [running]> on host ea4c9b9e2e97
[2022-08-17 19:17:16,604] {taskinstance.py:1591} INFO - Exporting the following env vars:
AIRFLOW_CTX_DAG_OWNER=Cavefish
AIRFLOW_CTX_DAG_ID=unitronics_ETL_v01
AIRFLOW_CTX_TASK_ID=extract
AIRFLOW_CTX_EXECUTION_DATE=2022-08-14T00:00:00+00:00
AIRFLOW_CTX_TRY_NUMBER=4
AIRFLOW_CTX_DAG_RUN_ID=scheduled__2022-08-14T00:00:00+00:00
[2022-08-17 19:17:16,613] {taskinstance.py:1909} ERROR - Task failed with exception
Traceback (most recent call last):
  File "/home/airflow/.local/lib/python3.7/site-packages/airflow/operators/python.py", line 171, in execute
    return_value = self.execute_callable()
  File "/home/airflow/.local/lib/python3.7/site-packages/airflow/operators/python.py", line 189, in execute_callable
    return self.python_callable(*self.op_args, **self.op_kwargs)
  File "/opt/airflow/dags/unitronics_ETL.py", line 95, in extractData
    device_df = concatDataFrame(super_df_device)
  File "/opt/airflow/dags/unitronics_ETL.py", line 54, in concatDataFrame
    df = pd.concat(df, axis=0)
  File "/home/airflow/.local/lib/python3.7/site-packages/pandas/util/_decorators.py", line 311, in wrapper
    return func(*args, **kwargs)
  File "/home/airflow/.local/lib/python3.7/site-packages/pandas/core/reshape/concat.py", line 304, in concat
    sort=sort,
  File "/home/airflow/.local/lib/python3.7/site-packages/pandas/core/reshape/concat.py", line 351, in __init__
    raise ValueError("No objects to concatenate")
ValueError: No objects to concatenate
[2022-08-17 19:17:16,624] {taskinstance.py:1420} INFO - Marking task as UP_FOR_RETRY. dag_id=unitronics_ETL_v01, task_id=extract, execution_date=20220814T000000, start_date=20220817T191716, end_date=20220817T191716
[2022-08-17 19:17:16,635] {standard_task_runner.py:97} ERROR - Failed to execute job 20 for task extract (No objects to concatenate; 1181)
[2022-08-17 19:17:16,671] {local_task_job.py:156} INFO - Task exited with return code 1
[2022-08-17 19:17:16,750] {local_task_job.py:273} INFO - 0 downstream tasks scheduled from follow-on schedule check
[2022-08-17 19:56:01,221] {taskinstance.py:1179} INFO - Dependencies all met for <TaskInstance: unitronics_ETL_v01.extract scheduled__2022-08-14T00:00:00+00:00 [queued]>
[2022-08-17 19:56:01,234] {taskinstance.py:1179} INFO - Dependencies all met for <TaskInstance: unitronics_ETL_v01.extract scheduled__2022-08-14T00:00:00+00:00 [queued]>
[2022-08-17 19:56:01,234] {taskinstance.py:1376} INFO - 
--------------------------------------------------------------------------------
[2022-08-17 19:56:01,235] {taskinstance.py:1377} INFO - Starting attempt 4 of 6
[2022-08-17 19:56:01,235] {taskinstance.py:1378} INFO - 
--------------------------------------------------------------------------------
[2022-08-17 19:56:01,251] {taskinstance.py:1397} INFO - Executing <Task(PythonOperator): extract> on 2022-08-14 00:00:00+00:00
[2022-08-17 19:56:01,258] {standard_task_runner.py:52} INFO - Started process 1241 to run task
[2022-08-17 19:56:01,262] {standard_task_runner.py:79} INFO - Running: ['***', 'tasks', 'run', 'unitronics_ETL_v01', 'extract', 'scheduled__2022-08-14T00:00:00+00:00', '--job-id', '28', '--raw', '--subdir', 'DAGS_FOLDER/unitronics_ETL.py', '--cfg-path', '/tmp/tmpvnijddx3', '--error-file', '/tmp/tmpunyw5a1b']
[2022-08-17 19:56:01,264] {standard_task_runner.py:80} INFO - Job 28: Subtask extract
[2022-08-17 19:56:01,354] {task_command.py:371} INFO - Running <TaskInstance: unitronics_ETL_v01.extract scheduled__2022-08-14T00:00:00+00:00 [running]> on host 8c93e37464e5
[2022-08-17 19:56:01,441] {taskinstance.py:1591} INFO - Exporting the following env vars:
AIRFLOW_CTX_DAG_OWNER=Cavefish
AIRFLOW_CTX_DAG_ID=unitronics_ETL_v01
AIRFLOW_CTX_TASK_ID=extract
AIRFLOW_CTX_EXECUTION_DATE=2022-08-14T00:00:00+00:00
AIRFLOW_CTX_TRY_NUMBER=4
AIRFLOW_CTX_DAG_RUN_ID=scheduled__2022-08-14T00:00:00+00:00
[2022-08-17 19:56:01,450] {taskinstance.py:1909} ERROR - Task failed with exception
Traceback (most recent call last):
  File "/home/airflow/.local/lib/python3.7/site-packages/airflow/operators/python.py", line 171, in execute
    return_value = self.execute_callable()
  File "/home/airflow/.local/lib/python3.7/site-packages/airflow/operators/python.py", line 189, in execute_callable
    return self.python_callable(*self.op_args, **self.op_kwargs)
  File "/opt/airflow/dags/unitronics_ETL.py", line 75, in extractData
    files = os.listdir(dir_name)
FileNotFoundError: [Errno 2] No such file or directory: 'C:/Unitronics Data Logs'
[2022-08-17 19:56:01,461] {taskinstance.py:1420} INFO - Marking task as UP_FOR_RETRY. dag_id=unitronics_ETL_v01, task_id=extract, execution_date=20220814T000000, start_date=20220817T195601, end_date=20220817T195601
[2022-08-17 19:56:01,472] {standard_task_runner.py:97} ERROR - Failed to execute job 28 for task extract ([Errno 2] No such file or directory: 'C:/Unitronics Data Logs'; 1241)
[2022-08-17 19:56:01,516] {local_task_job.py:156} INFO - Task exited with return code 1
[2022-08-17 19:56:01,557] {local_task_job.py:273} INFO - 0 downstream tasks scheduled from follow-on schedule check
[2022-08-17 21:32:56,682] {taskinstance.py:1179} INFO - Dependencies all met for <TaskInstance: unitronics_ETL_v01.extract scheduled__2022-08-14T00:00:00+00:00 [queued]>
[2022-08-17 21:32:56,692] {taskinstance.py:1179} INFO - Dependencies all met for <TaskInstance: unitronics_ETL_v01.extract scheduled__2022-08-14T00:00:00+00:00 [queued]>
[2022-08-17 21:32:56,692] {taskinstance.py:1376} INFO - 
--------------------------------------------------------------------------------
[2022-08-17 21:32:56,692] {taskinstance.py:1377} INFO - Starting attempt 4 of 6
[2022-08-17 21:32:56,692] {taskinstance.py:1378} INFO - 
--------------------------------------------------------------------------------
[2022-08-17 21:32:56,710] {taskinstance.py:1397} INFO - Executing <Task(PythonOperator): extract> on 2022-08-14 00:00:00+00:00
[2022-08-17 21:32:56,714] {standard_task_runner.py:52} INFO - Started process 1161 to run task
[2022-08-17 21:32:56,718] {standard_task_runner.py:79} INFO - Running: ['***', 'tasks', 'run', 'unitronics_ETL_v01', 'extract', 'scheduled__2022-08-14T00:00:00+00:00', '--job-id', '16', '--raw', '--subdir', 'DAGS_FOLDER/unitronics_ETL.py', '--cfg-path', '/tmp/tmp1mq74i4c', '--error-file', '/tmp/tmpnsp7sfn6']
[2022-08-17 21:32:56,719] {standard_task_runner.py:80} INFO - Job 16: Subtask extract
[2022-08-17 21:32:56,794] {task_command.py:371} INFO - Running <TaskInstance: unitronics_ETL_v01.extract scheduled__2022-08-14T00:00:00+00:00 [running]> on host 1b0f89009e2c
[2022-08-17 21:32:56,873] {taskinstance.py:1591} INFO - Exporting the following env vars:
AIRFLOW_CTX_DAG_OWNER=Cavefish
AIRFLOW_CTX_DAG_ID=unitronics_ETL_v01
AIRFLOW_CTX_TASK_ID=extract
AIRFLOW_CTX_EXECUTION_DATE=2022-08-14T00:00:00+00:00
AIRFLOW_CTX_TRY_NUMBER=4
AIRFLOW_CTX_DAG_RUN_ID=scheduled__2022-08-14T00:00:00+00:00
[2022-08-17 21:32:56,881] {taskinstance.py:1909} ERROR - Task failed with exception
Traceback (most recent call last):
  File "/home/airflow/.local/lib/python3.7/site-packages/airflow/operators/python.py", line 171, in execute
    return_value = self.execute_callable()
  File "/home/airflow/.local/lib/python3.7/site-packages/airflow/operators/python.py", line 189, in execute_callable
    return self.python_callable(*self.op_args, **self.op_kwargs)
  File "/opt/airflow/dags/unitronics_ETL.py", line 76, in extractData
    files = os.listdir(dir_name)
FileNotFoundError: [Errno 2] No such file or directory: '/Unitronics Data Logs/'
[2022-08-17 21:32:56,892] {taskinstance.py:1420} INFO - Marking task as UP_FOR_RETRY. dag_id=unitronics_ETL_v01, task_id=extract, execution_date=20220814T000000, start_date=20220817T213256, end_date=20220817T213256
[2022-08-17 21:32:56,904] {standard_task_runner.py:97} ERROR - Failed to execute job 16 for task extract ([Errno 2] No such file or directory: '/Unitronics Data Logs/'; 1161)
[2022-08-17 21:32:56,929] {local_task_job.py:156} INFO - Task exited with return code 1
[2022-08-17 21:32:56,970] {local_task_job.py:273} INFO - 0 downstream tasks scheduled from follow-on schedule check
