[2022-08-17 19:57:22,005] {taskinstance.py:1179} INFO - Dependencies all met for <TaskInstance: unitronics_ETL_v01.extract manual__2022-08-17T19:52:19.249375+00:00 [queued]>
[2022-08-17 19:57:22,015] {taskinstance.py:1179} INFO - Dependencies all met for <TaskInstance: unitronics_ETL_v01.extract manual__2022-08-17T19:52:19.249375+00:00 [queued]>
[2022-08-17 19:57:22,016] {taskinstance.py:1376} INFO - 
--------------------------------------------------------------------------------
[2022-08-17 19:57:22,017] {taskinstance.py:1377} INFO - Starting attempt 2 of 6
[2022-08-17 19:57:22,017] {taskinstance.py:1378} INFO - 
--------------------------------------------------------------------------------
[2022-08-17 19:57:22,033] {taskinstance.py:1397} INFO - Executing <Task(PythonOperator): extract> on 2022-08-17 19:52:19.249375+00:00
[2022-08-17 19:57:22,037] {standard_task_runner.py:52} INFO - Started process 1339 to run task
[2022-08-17 19:57:22,040] {standard_task_runner.py:79} INFO - Running: ['***', 'tasks', 'run', 'unitronics_ETL_v01', 'extract', 'manual__2022-08-17T19:52:19.249375+00:00', '--job-id', '33', '--raw', '--subdir', 'DAGS_FOLDER/unitronics_ETL.py', '--cfg-path', '/tmp/tmp27vdwf3m', '--error-file', '/tmp/tmp1bkt3a2p']
[2022-08-17 19:57:22,041] {standard_task_runner.py:80} INFO - Job 33: Subtask extract
[2022-08-17 19:57:22,104] {task_command.py:371} INFO - Running <TaskInstance: unitronics_ETL_v01.extract manual__2022-08-17T19:52:19.249375+00:00 [running]> on host 8c93e37464e5
[2022-08-17 19:57:22,174] {taskinstance.py:1591} INFO - Exporting the following env vars:
AIRFLOW_CTX_DAG_OWNER=Cavefish
AIRFLOW_CTX_DAG_ID=unitronics_ETL_v01
AIRFLOW_CTX_TASK_ID=extract
AIRFLOW_CTX_EXECUTION_DATE=2022-08-17T19:52:19.249375+00:00
AIRFLOW_CTX_TRY_NUMBER=2
AIRFLOW_CTX_DAG_RUN_ID=manual__2022-08-17T19:52:19.249375+00:00
[2022-08-17 19:57:22,181] {taskinstance.py:1909} ERROR - Task failed with exception
Traceback (most recent call last):
  File "/home/airflow/.local/lib/python3.7/site-packages/airflow/operators/python.py", line 171, in execute
    return_value = self.execute_callable()
  File "/home/airflow/.local/lib/python3.7/site-packages/airflow/operators/python.py", line 189, in execute_callable
    return self.python_callable(*self.op_args, **self.op_kwargs)
  File "/opt/airflow/dags/unitronics_ETL.py", line 75, in extractData
    files = os.listdir(dir_name)
FileNotFoundError: [Errno 2] No such file or directory: 'C:/Unitronics Data Logs'
[2022-08-17 19:57:22,193] {taskinstance.py:1420} INFO - Marking task as UP_FOR_RETRY. dag_id=unitronics_ETL_v01, task_id=extract, execution_date=20220817T195219, start_date=20220817T195722, end_date=20220817T195722
[2022-08-17 19:57:22,203] {standard_task_runner.py:97} ERROR - Failed to execute job 33 for task extract ([Errno 2] No such file or directory: 'C:/Unitronics Data Logs'; 1339)
[2022-08-17 19:57:22,212] {local_task_job.py:156} INFO - Task exited with return code 1
[2022-08-17 19:57:22,250] {local_task_job.py:273} INFO - 0 downstream tasks scheduled from follow-on schedule check
